Workbook

Sheet Hoja1
A1: INTERVALO DE CONSUMO | D1: ENERGÍA | H1: POTENCIA | M1: REACTIVA Y FP | O1: FIJOS | P1: ENERGÍA | S1: CARGO CAPACIDAD-DISTRIBUCIÓN | W1: $ ENERGÍA | AC1: FACTOR DE POTENCIA | AE1: FACTURACIÓN CALCULADA | AI1: FACTURACIÓN RECIBO | AJ1: MODALIDAD | AK1: HORAS POR PERIODO | AN1: HORAS SOLARES | AQ1: CONSUMO EN HORAS SOLARES | AW1: SISTEMAS FOTOVOLTAICOS | BF1: SISTEMA PROPUESTO | CA1: $ ENERGÍA | CG1: FACTOR DE POTENCIA | CI1: FACTURACIÓN CALCULADA | CM1: AHORRO ESTIMADO
A2: PERIODO | B2: PERIODO | C2: DÍAS | D2: kWh BASE | E2: kWh INTERMEDIA | F2: kWh PUNTA | G2: kWh total | H2: kW BASE | I2: kW INTERMEDIA | J2: kW PUNTA | K2: kW MÁX | L2: POTENCIA CALCULADA | M2: kVARh | N2: FP | O2: CARGO FIJO ($/MES) | P2: kWh BASE ($/kWh) | Q2: kWh INTERMEDIA ($/kWh) | R2: kWh PUNTA ($/kWh) | S2: DISTRIBUCIÓN ($/kW) | T2: CAPACIDAD ($/kW) | U2: POTENCIA PARA EL CARGO POR CAPACIDAD | V2: POTENCIA PARA EL CARGO POR DISTRIBUCIÓN | W2: $ BASE | X2: $ INTERMEDIO | Y2: $ PUNTA | Z2: $ DISTRIBUCIÓN | AA2: $ CAPACIDAD | AB2: $ ENERGÍA | AC2: FP | AD2: $ FP | AE2: SUBTOTAL | AF2: IVA 16% | AG2: DAP | AH2: TOTAL | AI2: TOTAL A PAGAR (MXN) | AJ2: CONTRAPRESTACIÓN | AK2: HORAS BASE | AL2: HORAS INTERMEDIA | AM2: HORAS PUNTA | AN2: HORAS BASE SOLARES | AO2: HORAS INTERMEDIA SOLARES | AP2: TOTAL DE HORAS SOLARES | AQ2: CONSUMO BASE EN HORAS SOLARES | AR2: CONSUMO INTERMEDIO EN HORAS SOLARES | AS2: CONSUMO EN HORAS SOLARES (kWh) | AT2: %CONSUMO EN BASE RESPECTO AL TOTAL EN HORAS SOLARES | AU2: %CONSUMO EN INTERMEDIO RESPECTO AL TOTAL EN HORAS SOLARES | AV2: %CONSUMO EN HORAS SOLARES RESPECTO AL CONSUMO TOTAL | AW2: HSP (NASA) | AX2: EFICIENCIA | AY2: POTENCIA DEL MÓDULO (kW) | AZ2: PSFV 100% | BA2: #MÓDULOS 100% | BB2: PSFV PERIODO INTERMEDIO | BC2: # MÓDULOS PERIODO INTERMEDIO | BD2: PSFV HORAS SOLARES | BE2: #MÓDULOS HORAS SOLARES | BF2: SISTEMA PROPUESTO (kW) | BG2: GENERACIÓN CON SFV PROPUESTO (kWh) | BH2: GENERACIÓN CON SFV EN BASE | BI2: GENERACIÓN CON SFV EN INTERMEDIA | BJ2: EXCEDENTES/FALTANTES PROYECTADOS | BK2: NUEVO CONSUMO ESPERADO EN BASE (kWh) | BL2: NUEVO CONSUMO ESPERADO EN INTERMEDIO (kWh) | BM2: NUEVO CONSUMO ESPERADO (kWh) | BN2: PORCENTAJE DE ABATIMIENTO DE CONSUMO ENERGÉTICO | BO2: =BK2 -> NUEVO CONSUMO ESPERADO EN BASE (kWh) | BP2: =BL2 -> NUEVO CONSUMO ESPERADO EN INTERMEDIO (kWh) | BQ2: =F2 -> kWh PUNTA | BR2: kWh TOTAL | BS2: POTENCIA CALCULADA (kW) | BT2: =N2 -> FP | BU2: =O2 -> CARGO FIJO ($/MES) | BV2: =P2 -> kWh BASE ($/kWh) | BW2: =Q2 -> kWh INTERMEDIA ($/kWh) | BX2: =R2 -> kWh PUNTA ($/kWh) | BY2: =S2 -> DISTRIBUCIÓN ($/kW) | BZ2: =T2 -> CAPACIDAD ($/kW) | CA2: $ BASE | CB2: $ INTERMEDIO | CC2: $ PUNTA | CD2: $ DISTRIBUCIÓN | CE2: $ CAPACIDAD | CF2: $ ENERGÍA | CG2: =AC2 -> FP | CH2: =AD2 -> $ FP | CI2: SUBTOTAL | CJ2: IVA 16% | CK2: DAP | CL2: TOTAL A PAGAR CON SISTEMA FOTOVOLTAICO | CM2: AHORRO
A3: 45291 | B3: 45322 | C3: =B3-A3 -> 31 | D3: 274750 | E3: 528463 | F3: 141986 | G3: =SUM(D3:F3) -> 945199 | H3: 1732 | I3: 1798 | J3: 1815 | K3: 1815 | L3: =G3/(24*C3*0.57) -> 2228.8224 | M3: 325156 | N3: 94.56 | O3: 362.6 | P3: 1.0702 | Q3: 1.9081 | R3: 2.1752 | S3: 101.75 | T3: 401.05 | U3: =MIN(J3,L3) -> 1815 | V3: =MIN(K3:L3) -> 1815 | W3: =D3*P3 -> 294037.45 | X3: =E3*Q3 -> 1008360.3 | Y3: =F3*R3 -> 308847.95 | Z3: =S3*V3 -> 184676.25 | AA3: =T3*U3 -> 727905.75 | AB3: =SUM(W3:AA3) -> 2523827.6 | AC3: =IF(N3<95,ROUND((3/5)*((95/N3)-1),3), ROUND((1/4)*(1-(90/N3)),3)) -> 0.003 | AD3: =(AB3+O3)*AC3 -> 7572.5707 | AE3: =SUM(O3,AB3,AD3) -> 2531762.8 | AF3: =AE3*0.16 -> 405082.05 | AG3: =AE3*0.08 -> 202541.03 | AH3: =AE3+AF3+AG3 -> 3139385.9 | AI3: 3139386.7 | AK3: =AK15 -> 242 | AL3: =AL15 -> 402 | AM3: =AM15 -> 100 | AN3: =AN15 -> 52 | AO3: =AO15 -> 320 | AP3: =SUM(AN3:AO3) -> 372 | AQ3: =D3*AN3/AK3 -> 59037.19 | AR3: =E3*AO3/AL3 -> 420667.06 | AS3: =SUM(AQ3,AR3) -> 479704.25 | AT3: =AQ3/AS3 -> 0.12306997 | AU3: =AR3/AS3 -> 0.87693003 | AV3: =AS3/G3 -> 0.50751668 | AW3: 4.6486 | AX3: 0.85 | AY3: 0.62 | AZ3: =G3/(C3*AW3*AX3) -> 7716.5017 | BA3: =ROUNDUP(AZ3/AY3,0) -> 12446 | BB3: =E3/(C3*AW3*AX3) -> 4314.3144 | BC3: =ROUNDUP(BB3/AY3,0) -> 6959 | BD3: =AS3/(C3*AW3*AX3) -> 3916.2533 | BE3: =ROUNDUP(BD3/AY3,0) -> 6317 | BF3: =4560*AY3 -> 2827.2 | BG3: =BF3*C3*AW3*AX3 -> 346305.45 | BH3: =BG3*AT3 -> 42619.803 | BI3: =BG3*AU3 -> 303685.65 | BJ3: =ROUNDUP(BG3-AS3,0) -> -133399 | BK3: =D3-BH3 -> 232130.2 | BL3: =E3-BI3 -> 224777.35 | BM3: =IF(BJ3<0,G3-BG3,G3-BG3+BJ3) -> 598893.55 | BN3: =IF(BJ3<0,BG3/G3,(BG3-BJ3)/G3) -> 0.36638364 | BO3: =BK3 -> 232130.2 | BP3: =BL3 -> 224777.35 | BQ3: =F3 -> 141986 | BR3: =SUM(BO3:BQ3) -> 598893.55 | BS3: =BR3/(24*C3*0.57) -> 1412.2183 | BT3: =N3 -> 94.56 | BU3: =O3 -> 362.6 | BV3: =P3 -> 1.0702 | BW3: =Q3 -> 1.9081 | BX3: =R3 -> 2.1752 | BY3: =S3 -> 101.75 | BZ3: =T3 -> 401.05 | CA3: =BO3*BV3 -> 248425.74 | CB3: =BP3*BW3 -> 428897.66 | CC3: =BQ3*BX3 -> 308847.95 | CD3: =BS3*BY3 -> 143693.21 | CE3: =BS3*BZ3 -> 566370.16 | CF3: =SUM(CA3:CC3) -> 986171.35 | CG3: =AC3 -> 0.003 | CH3: =AD3 -> 7572.5707 | CI3: =SUM(BU3,CF3,CH3) -> 994106.52 | CJ3: =CI3*0.16 -> 159057.04 | CK3: =CI3*0.08 -> 79528.521 | CL3: =SUM(CI3,CJ3,CK3) -> 1232692.1 | CM3: =AI3-CL3 -> 1906694.6
A4: 45322 | B4: 45351 | C4: =B4-A4 -> 29 | D4: 304500 | E4: 560167 | F4: 150228 | G4: =SUM(D4:F4) -> 1014895 | H4: 1749 | I4: 1904 | J4: 1947 | K4: 1947 | L4: =G4/(24*C4*0.57) -> 2558.2149 | M4: 361949 | N4: 94.19 | O4: 362.6 | P4: 1.0753 | Q4: 1.918 | R4: 2.1867 | S4: 101.75 | T4: 403.37 | U4: =MIN(J4,L4) -> 1947 | V4: =MIN(K4:L4) -> 1947 | W4: =D4*P4 -> 327428.85 | X4: =E4*Q4 -> 1074400.3 | Y4: =F4*R4 -> 328503.57 | Z4: =S4*V4 -> 198107.25 | AA4: =T4*U4 -> 785361.39 | AB4: =SUM(W4:AA4) -> 2713801.4 | AC4: =IF(N4<95,ROUND((3/5)*((95/N4)-1),3), ROUND((1/4)*(1-(90/N4)),3)) -> 0.005 | AD4: =(AB4+O4)*AC4 -> 13570.82 | AE4: =SUM(O4,AB4,AD4) -> 2727734.8 | AF4: =AE4*0.16 -> 436437.57 | AG4: =AE4*0.08 -> 218218.78 | AH4: =AE4+AF4+AG4 -> 3382391.1 | AI4: 3382391.9 | AK4: =AK16 -> 224 | AL4: =AL16 -> 360 | AM4: =AM16 -> 88 | AN4: =AN16 -> 52 | AO4: =AO16 -> 284 | AP4: =SUM(AN4:AO4) -> 336 | AQ4: =D4*AN4/AK4 -> 70687.5 | AR4: =E4*AO4/AL4 -> 441909.52 | AS4: =SUM(AQ4,AR4) -> 512597.02 | AT4: =AQ4/AS4 -> 0.13790072 | AU4: =AR4/AS4 -> 0.86209928 | AV4: =AS4/G4 -> 0.50507395 | AW4: 5.6314 | AX4: 0.85 | AY4: 0.62 | AZ4: =G4/(C4*AW4*AX4) -> 7311.1857 | BA4: =ROUNDUP(AZ4/AY4,0) -> 11793 | BB4: =E4/(C4*AW4*AX4) -> 4035.378 | BC4: =ROUNDUP(BB4/AY4,0) -> 6509 | BD4: =AS4/(C4*AW4*AX4) -> 3692.6894 | BE4: =ROUNDUP(BD4/AY4,0) -> 5956 | BF4: =4560*AY4 -> 2827.2 | BG4: =BF4*C4*AW4*AX4 -> 392454.97 | BH4: =BG4*AT4 -> 54119.824 | BI4: =BG4*AU4 -> 338335.15 | BJ4: =ROUNDUP(BG4-AS4,0) -> -120143 | BK4: =D4-BH4 -> 250380.18 | BL4: =E4-BI4 -> 221831.85 | BM4: =IF(BJ4<0,G4-BG4,G4-BG4+BJ4) -> 622440.03 | BN4: =IF(BJ4<0,BG4/G4,(BG4-BJ4)/G4) -> 0.38669514 | BO4: =BK4 -> 250380.18 | BP4: =BL4 -> 221831.85 | BQ4: =F4 -> 150228 | BR4: =SUM(BO4:BQ4) -> 622440.03 | BS4: =BR4/(24*C4*0.57) -> 1568.9656 | BT4: =N4 -> 94.19 | BU4: =O4 -> 362.6 | BV4: =P4 -> 1.0753 | BW4: =Q4 -> 1.918 | BX4: =R4 -> 2.1867 | BY4: =S4 -> 101.75 | BZ4: =T4 -> 403.37 | CA4: =BO4*BV4 -> 269233.8 | CB4: =BP4*BW4 -> 425473.5 | CC4: =BQ4*BX4 -> 328503.57 | CD4: =BS4*BY4 -> 159642.25 | CE4: =BS4*BZ4 -> 632873.65 | CF4: =SUM(CA4:CC4) -> 1023210.9 | CG4: =AC4 -> 0.005 | CH4: =AD4 -> 13570.82 | CI4: =SUM(BU4,CF4,CH4) -> 1037144.3 | CJ4: =CI4*0.16 -> 165943.09 | CK4: =CI4*0.08 -> 82971.543 | CL4: =SUM(CI4,CJ4,CK4) -> 1286058.9 | CM4: =AI4-CL4 -> 2096332.9
A5: 45351 | B5: 45382 | C5: =B5-A5 -> 31 | D5: 339500 | E5: 643769 | F5: 160629 | G5: =SUM(D5:F5) -> 1143898 | H5: 1860 | I5: 2012 | J5: 1847 | K5: 2012 | L5: =G5/(24*C5*0.57) -> 2697.3637 | M5: 404533 | N5: 94.28 | O5: 362.6 | P5: 1.0865 | Q5: 1.9398 | R5: 2.2119 | S5: 101.75 | T5: 408.46 | U5: =MIN(J5,L5) -> 1847 | V5: =MIN(K5:L5) -> 2012 | W5: =D5*P5 -> 368866.75 | X5: =E5*Q5 -> 1248783.1 | Y5: =F5*R5 -> 355295.29 | Z5: =S5*V5 -> 204721 | AA5: =T5*U5 -> 754425.62 | AB5: =SUM(W5:AA5) -> 2932091.8 | AC5: =IF(N5<95,ROUND((3/5)*((95/N5)-1),3), ROUND((1/4)*(1-(90/N5)),3)) -> 0.005 | AD5: =(AB5+O5)*AC5 -> 14662.272 | AE5: =SUM(O5,AB5,AD5) -> 2947116.6 | AF5: =AE5*0.16 -> 471538.66 | AG5: =AE5*0.08 -> 235769.33 | AH5: =AE5+AF5+AG5 -> 3654424.6 | AI5: 3654425.5 | AK5: =AK17 -> 256 | AL5: =AL17 -> 394 | AM5: =AM17 -> 94 | AN5: =AN17 -> 65 | AO5: =AO17 -> 307 | AP5: =SUM(AN5:AO5) -> 372 | AQ5: =D5*AN5/AK5 -> 86201.172 | AR5: =E5*AO5/AL5 -> 501616.96 | AS5: =SUM(AQ5,AR5) -> 587818.13 | AT5: =AQ5/AS5 -> 0.14664599 | AU5: =AR5/AS5 -> 0.85335401 | AV5: =AS5/G5 -> 0.51387286 | AW5: 7.0704 | AX5: 0.85 | AY5: 0.62 | AZ5: =G5/(C5*AW5*AX5) -> 6139.9198 | BA5: =ROUNDUP(AZ5/AY5,0) -> 9904 | BB5: =E5/(C5*AW5*AX5) -> 3455.4567 | BC5: =ROUNDUP(BB5/AY5,0) -> 5574 | BD5: =AS5/(C5*AW5*AX5) -> 3155.1381 | BE5: =ROUNDUP(BD5/AY5,0) -> 5089 | BF5: =4560*AY5 -> 2827.2 | BG5: =BF5*C5*AW5*AX5 -> 526721.61 | BH5: =BG5*AT5 -> 77241.612 | BI5: =BG5*AU5 -> 449480 | BJ5: =ROUNDUP(BG5-AS5,0) -> -61097 | BK5: =D5-BH5 -> 262258.39 | BL5: =E5-BI5 -> 194289 | BM5: =IF(BJ5<0,G5-BG5,G5-BG5+BJ5) -> 617176.39 | BN5: =IF(BJ5<0,BG5/G5,(BG5-BJ5)/G5) -> 0.46046204 | BO5: =BK5 -> 262258.39 | BP5: =BL5 -> 194289 | BQ5: =F5 -> 160629 | BR5: =SUM(BO5:BQ5) -> 617176.39 | BS5: =BR5/(24*C5*0.57) -> 1455.3301 | BT5: =N5 -> 94.28 | BU5: =O5 -> 362.6 | BV5: =P5 -> 1.0865 | BW5: =Q5 -> 1.9398 | BX5: =R5 -> 2.2119 | BY5: =S5 -> 101.75 | BZ5: =T5 -> 408.46 | CA5: =BO5*BV5 -> 284943.74 | CB5: =BP5*BW5 -> 376881.81 | CC5: =BQ5*BX5 -> 355295.29 | CD5: =BS5*BY5 -> 148079.84 | CE5: =BS5*BZ5 -> 594444.13 | CF5: =SUM(CA5:CC5) -> 1017120.8 | CG5: =AC5 -> 0.005 | CH5: =AD5 -> 14662.272 | CI5: =SUM(BU5,CF5,CH5) -> 1032145.7 | CJ5: =CI5*0.16 -> 165143.31 | CK5: =CI5*0.08 -> 82571.656 | CL5: =SUM(CI5,CJ5,CK5) -> 1279860.7 | CM5: =AI5-CL5 -> 2374564.8
A6: 45382 | B6: 45412 | C6: =B6-A6 -> 30 | D6: 337750 | E6: 712401 | F6: 92039 | G6: =SUM(D6:F6) -> 1142190 | H6: 1698 | I6: 1995 | J6: 105 | K6: 2012 | L6: =G6/(24*C6*0.57) -> 2783.114 | M6: 378731 | N6: 94.93 | O6: 362.6 | P6: 1.0865 | Q6: 1.9399 | R6: 2.212 | S6: 101.75 | T6: 408.47 | U6: =MIN(J6,L6) -> 105 | V6: =MIN(K6:L6) -> 2012 | W6: =D6*P6 -> 366965.38 | X6: =E6*Q6 -> 1381986.7 | Y6: =F6*R6 -> 203590.27 | Z6: =S6*V6 -> 204721 | AA6: =T6*U6 -> 42889.35 | AB6: =SUM(W6:AA6) -> 2200152.7 | AC6: =IF(N6<95,ROUND((3/5)*((95/N6)-1),3), ROUND((1/4)*(1-(90/N6)),3)) -> 0 | AD6: =(AB6+O6)*AC6 -> 0 | AE6: =SUM(O6,AB6,AD6) -> 2200515.3 | AF6: =AE6*0.16 -> 352082.45 | AG6: =AE6*0.08 -> 176041.22 | AH6: =AE6+AF6+AG6 -> 2728639 | AI6: 2667773.1 | AK6: =AK18 -> 237 | AL6: =AL18 -> 427 | AM6: =AM18 -> 56 | AN6: =AN18 -> 49 | AO6: =AO18 -> 311 | AP6: =SUM(AN6:AO6) -> 360 | AQ6: =D6*AN6/AK6 -> 69830.169 | AR6: =E6*AO6/AL6 -> 518868.18 | AS6: =SUM(AQ6,AR6) -> 588698.34 | AT6: =AQ6/AS6 -> 0.11861791 | AU6: =AR6/AS6 -> 0.88138209 | AV6: =AS6/G6 -> 0.51541192 | AW6: 7.7875 | AX6: 0.85 | AY6: 0.62 | AZ6: =G6/(C6*AW6*AX6) -> 5751.7515 | BA6: =ROUNDUP(AZ6/AY6,0) -> 9278 | BB6: =E6/(C6*AW6*AX6) -> 3587.4535 | BC6: =ROUNDUP(BB6/AY6,0) -> 5787 | BD6: =AS6/(C6*AW6*AX6) -> 2964.5213 | BE6: =ROUNDUP(BD6/AY6,0) -> 4782 | BF6: =4560*AY6 -> 2827.2 | BG6: =BF6*C6*AW6*AX6 -> 561428.91 | BH6: =BG6*AT6 -> 66595.525 | BI6: =BG6*AU6 -> 494833.38 | BJ6: =ROUNDUP(BG6-AS6,0) -> -27270 | BK6: =D6-BH6 -> 271154.47 | BL6: =E6-BI6 -> 217567.62 | BM6: =IF(BJ6<0,G6-BG6,G6-BG6+BJ6) -> 580761.09 | BN6: =IF(BJ6<0,BG6/G6,(BG6-BJ6)/G6) -> 0.49153723 | BO6: =BK6 -> 271154.47 | BP6: =BL6 -> 217567.62 | BQ6: =F6 -> 92039 | BR6: =SUM(BO6:BQ6) -> 580761.09 | BS6: =BR6/(24*C6*0.57) -> 1415.1099 | BT6: =N6 -> 94.93 | BU6: =O6 -> 362.6 | BV6: =P6 -> 1.0865 | BW6: =Q6 -> 1.9399 | BX6: =R6 -> 2.212 | BY6: =S6 -> 101.75 | BZ6: =T6 -> 408.47 | CA6: =BO6*BV6 -> 294609.34 | CB6: =BP6*BW6 -> 422059.42 | CC6: =BQ6*BX6 -> 203590.27 | CD6: =BS6*BY6 -> 143987.43 | CE6: =BS6*BZ6 -> 578029.93 | CF6: =SUM(CA6:CC6) -> 920259.02 | CG6: =AC6 -> 0 | CH6: =AD6 -> 0 | CI6: =SUM(BU6,CF6,CH6) -> 920621.62 | CJ6: =CI6*0.16 -> 147299.46 | CK6: =CI6*0.08 -> 73649.73 | CL6: =SUM(CI6,CJ6,CK6) -> 1141570.8 | CM6: =AI6-CL6 -> 1526202.3
A7: 45412 | B7: 45443 | C7: =B7-A7 -> 31 | D7: 339153 | E7: 667425 | F7: 73815 | G7: =SUM(D7:F7) -> 1080393 | H7: 1725 | I7: 1928 | J7: 1947 | K7: 1947 | L7: =G7/(24*C7*0.57) -> 2547.616 | M7: 422677 | N7: 93.13 | O7: 362.6 | P7: 1.0865 | Q7: 1.9399 | R7: 2.212 | S7: 101.75 | T7: 408.47 | U7: =MIN(J7,L7) -> 1947 | V7: =MIN(K7:L7) -> 1947 | W7: =D7*P7 -> 368489.73 | X7: =E7*Q7 -> 1294737.8 | Y7: =F7*R7 -> 163278.78 | Z7: =S7*V7 -> 198107.25 | AA7: =T7*U7 -> 795291.09 | AB7: =SUM(W7:AA7) -> 2819904.6 | AC7: =IF(N7<95,ROUND((3/5)*((95/N7)-1),3), ROUND((1/4)*(1-(90/N7)),3)) -> 0.012 | AD7: =(AB7+O7)*AC7 -> 33843.207 | AE7: =SUM(O7,AB7,AD7) -> 2854110.4 | AF7: =AE7*0.16 -> 456657.67 | AG7: =AE7*0.08 -> 228328.83 | AH7: =AE7+AF7+AG7 -> 3539096.9 | AI7: 3539097 | AK7: =AK19 -> 242 | AL7: =AL19 -> 456 | AM7: =AM19 -> 46 | AN7: =AN19 -> 48 | AO7: =AO19 -> 324 | AP7: =SUM(AN7:AO7) -> 372 | AQ7: =D7*AN7/AK7 -> 67270.017 | AR7: =E7*AO7/AL7 -> 474223.03 | AS7: =SUM(AQ7,AR7) -> 541493.04 | AT7: =AQ7/AS7 -> 0.12423062 | AU7: =AR7/AS7 -> 0.87576938 | AV7: =AS7/G7 -> 0.50120007 | AW7: 7.8698 | AX7: 0.85 | AY7: 0.62 | AZ7: =G7/(C7*AW7*AX7) -> 5209.9967 | BA7: =ROUNDUP(AZ7/AY7,0) -> 8404 | BB7: =E7/(C7*AW7*AX7) -> 3218.5344 | BC7: =ROUNDUP(BB7/AY7,0) -> 5192 | BD7: =AS7/(C7*AW7*AX7) -> 2611.2507 | BE7: =ROUNDUP(BD7/AY7,0) -> 4212 | BF7: =4560*AY7 -> 2827.2 | BG7: =BF7*C7*AW7*AX7 -> 586274.29 | BH7: =BG7*AT7 -> 72833.218 | BI7: =BG7*AU7 -> 513441.07 | BJ7: =ROUNDUP(BG7-AS7,0) -> 44782 | BK7: =D7-BH7 -> 266319.78 | BL7: =E7-BI7 -> 153983.93 | BM7: =IF(BJ7<0,G7-BG7,G7-BG7+BJ7) -> 538900.71 | BN7: =IF(BJ7<0,BG7/G7,(BG7-BJ7)/G7) -> 0.50119937 | BO7: =BK7 -> 266319.78 | BP7: =BL7 -> 153983.93 | BQ7: =F7 -> 73815 | BR7: =SUM(BO7:BQ7) -> 494118.71 | BS7: =BR7/(24*C7*0.57) -> 1165.1545 | BT7: =N7 -> 93.13 | BU7: =O7 -> 362.6 | BV7: =P7 -> 1.0865 | BW7: =Q7 -> 1.9399 | BX7: =R7 -> 2.212 | BY7: =S7 -> 101.75 | BZ7: =T7 -> 408.47 | CA7: =BO7*BV7 -> 289356.44 | CB7: =BP7*BW7 -> 298713.43 | CC7: =BQ7*BX7 -> 163278.78 | CD7: =BS7*BY7 -> 118554.47 | CE7: =BS7*BZ7 -> 475930.65 | CF7: =SUM(CA7:CC7) -> 751348.65 | CG7: =AC7 -> 0.012 | CH7: =AD7 -> 33843.207 | CI7: =SUM(BU7,CF7,CH7) -> 785554.46 | CJ7: =CI7*0.16 -> 125688.71 | CK7: =CI7*0.08 -> 62844.357 | CL7: =SUM(CI7,CJ7,CK7) -> 974087.53 | CM7: =AI7-CL7 -> 2565009.5
A8: 45443 | B8: 45473 | C8: =B8-A8 -> 30 | D8: 336156 | E8: 663345 | F8: 72019 | G8: =SUM(D8:F8) -> 1071520 | H8: 1720 | I8: 1968 | J8: 1971 | K8: 1971 | L8: =G8/(24*C8*0.57) -> 2610.9162 | M8: 418685 | N8: 93.14 | O8: 362.6 | P8: 1.0865 | Q8: 1.9399 | R8: 2.212 | S8: 101.75 | T8: 408.47 | U8: =MIN(J8,L8) -> 1971 | V8: =MIN(K8:L8) -> 1971 | W8: =D8*P8 -> 365233.49 | X8: =E8*Q8 -> 1286823 | Y8: =F8*R8 -> 159306.03 | Z8: =S8*V8 -> 200549.25 | AA8: =T8*U8 -> 805094.37 | AB8: =SUM(W8:AA8) -> 2817006.1 | AC8: =IF(N8<95,ROUND((3/5)*((95/N8)-1),3), ROUND((1/4)*(1-(90/N8)),3)) -> 0.012 | AD8: =(AB8+O8)*AC8 -> 33808.424 | AE8: =SUM(O8,AB8,AD8) -> 2851177.1 | AF8: =AE8*0.16 -> 456188.34 | AG8: =AE8*0.08 -> 228094.17 | AH8: =AE8+AF8+AG8 -> 3535459.6 | AI8: 3535459.6 | AK8: =AK20 -> 250 | AL8: =AL20 -> 430 | AM8: =AM20 -> 40 | AN8: =AN20 -> 60 | AO8: =AO20 -> 300 | AP8: =SUM(AN8:AO8) -> 360 | AQ8: =D8*AN8/AK8 -> 80677.44 | AR8: =E8*AO8/AL8 -> 462798.84 | AS8: =SUM(AQ8,AR8) -> 543476.28 | AT8: =AQ8/AS8 -> 0.14844703 | AU8: =AR8/AS8 -> 0.85155297 | AV8: =AS8/G8 -> 0.50720124 | AW8: 6.4774 | AX8: 0.85 | AY8: 0.62 | AZ8: =G8/(C8*AW8*AX8) -> 6487.2313 | BA8: =ROUNDUP(AZ8/AY8,0) -> 10464 | BB8: =E8/(C8*AW8*AX8) -> 4016.0449 | BC8: =ROUNDUP(BB8/AY8,0) -> 6478 | BD8: =AS8/(C8*AW8*AX8) -> 3290.3318 | BE8: =ROUNDUP(BD8/AY8,0) -> 5307 | BF8: =4560*AY8 -> 2827.2 | BG8: =BF8*C8*AW8*AX8 -> 466979.08 | BH8: =BG8*AT8 -> 69321.659 | BI8: =BG8*AU8 -> 397657.43 | BJ8: =ROUNDUP(BG8-AS8,0) -> -76498 | BK8: =D8-BH8 -> 266834.34 | BL8: =E8-BI8 -> 265687.57 | BM8: =IF(BJ8<0,G8-BG8,G8-BG8+BJ8) -> 604540.92 | BN8: =IF(BJ8<0,BG8/G8,(BG8-BJ8)/G8) -> 0.43580996 | BO8: =BK8 -> 266834.34 | BP8: =BL8 -> 265687.57 | BQ8: =F8 -> 72019 | BR8: =SUM(BO8:BQ8) -> 604540.92 | BS8: =BR8/(24*C8*0.57) -> 1473.0529 | BT8: =N8 -> 93.14 | BU8: =O8 -> 362.6 | BV8: =P8 -> 1.0865 | BW8: =Q8 -> 1.9399 | BX8: =R8 -> 2.212 | BY8: =S8 -> 101.75 | BZ8: =T8 -> 408.47 | CA8: =BO8*BV8 -> 289915.51 | CB8: =BP8*BW8 -> 515407.33 | CC8: =BQ8*BX8 -> 159306.03 | CD8: =BS8*BY8 -> 149883.13 | CE8: =BS8*BZ8 -> 601697.92 | CF8: =SUM(CA8:CC8) -> 964628.86 | CG8: =AC8 -> 0.012 | CH8: =AD8 -> 33808.424 | CI8: =SUM(BU8,CF8,CH8) -> 998799.89 | CJ8: =CI8*0.16 -> 159807.98 | CK8: =CI8*0.08 -> 79903.991 | CL8: =SUM(CI8,CJ8,CK8) -> 1238511.9 | CM8: =AI8-CL8 -> 2296947.8
A9: 45473 | B9: 45504 | C9: =B9-A9 -> 31 | D9: 312310 | E9: 685539 | F9: 78527 | G9: =SUM(D9:F9) -> 1076376 | H9: 1693 | I9: 1911 | J9: 1904 | K9: 1911 | L9: =G9/(24*C9*0.57) -> 2538.1437 | M9: 412155 | N9: 93.39 | O9: 362.6 | P9: 1.1119 | Q9: 1.9894 | R9: 2.2692 | S9: 101.75 | T9: 420.02 | U9: =MIN(J9,L9) -> 1904 | V9: =MIN(K9:L9) -> 1911 | W9: =D9*P9 -> 347257.49 | X9: =E9*Q9 -> 1363811.3 | Y9: =F9*R9 -> 178193.47 | Z9: =S9*V9 -> 194444.25 | AA9: =T9*U9 -> 799718.08 | AB9: =SUM(W9:AA9) -> 2883424.6 | AC9: =IF(N9<95,ROUND((3/5)*((95/N9)-1),3), ROUND((1/4)*(1-(90/N9)),3)) -> 0.01 | AD9: =(AB9+O9)*AC9 -> 28837.872 | AE9: =SUM(O9,AB9,AD9) -> 2912625 | AF9: =AE9*0.16 -> 466020.01 | AG9: =AE9*0.08 -> 233010 | AH9: =AE9+AF9+AG9 -> 3611655.1 | AI9: 3611655.7 | AK9: =AK21 -> 242 | AL9: =AL21 -> 456 | AM9: =AM21 -> 46 | AN9: =AN21 -> 48 | AO9: =AO21 -> 324 | AP9: =SUM(AN9:AO9) -> 372 | AQ9: =D9*AN9/AK9 -> 61945.785 | AR9: =E9*AO9/AL9 -> 487093.5 | AS9: =SUM(AQ9,AR9) -> 549039.29 | AT9: =AQ9/AS9 -> 0.11282578 | AU9: =AR9/AS9 -> 0.88717422 | AV9: =AS9/G9 -> 0.51008131 | AW9: 5.573 | AX9: 0.85 | AY9: 0.62 | AZ9: =G9/(C9*AW9*AX9) -> 7329.8374 | BA9: =ROUNDUP(AZ9/AY9,0) -> 11823 | BB9: =E9/(C9*AW9*AX9) -> 4668.3403 | BC9: =ROUNDUP(BB9/AY9,0) -> 7530 | BD9: =AS9/(C9*AW9*AX9) -> 3738.8131 | BE9: =ROUNDUP(BD9/AY9,0) -> 6031 | BF9: =4560*AY9 -> 2827.2 | BG9: =BF9*C9*AW9*AX9 -> 415170.22 | BH9: =BG9*AT9 -> 46841.904 | BI9: =BG9*AU9 -> 368328.32 | BJ9: =ROUNDUP(BG9-AS9,0) -> -133870 | BK9: =D9-BH9 -> 265468.1 | BL9: =E9-BI9 -> 317210.68 | BM9: =IF(BJ9<0,G9-BG9,G9-BG9+BJ9) -> 661205.78 | BN9: =IF(BJ9<0,BG9/G9,(BG9-BJ9)/G9) -> 0.38571115 | BO9: =BK9 -> 265468.1 | BP9: =BL9 -> 317210.68 | BQ9: =F9 -> 78527 | BR9: =SUM(BO9:BQ9) -> 661205.78 | BS9: =BR9/(24*C9*0.57) -> 1559.1534 | BT9: =N9 -> 93.39 | BU9: =O9 -> 362.6 | BV9: =P9 -> 1.1119 | BW9: =Q9 -> 1.9894 | BX9: =R9 -> 2.2692 | BY9: =S9 -> 101.75 | BZ9: =T9 -> 420.02 | CA9: =BO9*BV9 -> 295173.98 | CB9: =BP9*BW9 -> 631058.93 | CC9: =BQ9*BX9 -> 178193.47 | CD9: =BS9*BY9 -> 158643.86 | CE9: =BS9*BZ9 -> 654875.62 | CF9: =SUM(CA9:CC9) -> 1104426.4 | CG9: =AC9 -> 0.01 | CH9: =AD9 -> 28837.872 | CI9: =SUM(BU9,CF9,CH9) -> 1133626.8 | CJ9: =CI9*0.16 -> 181380.3 | CK9: =CI9*0.08 -> 90690.148 | CL9: =SUM(CI9,CJ9,CK9) -> 1405697.3 | CM9: =AI9-CL9 -> 2205958.4
A10: 45504 | B10: 45535 | C10: =B10-A10 -> 31 | D10: 332002 | E10: 706495 | F10: 78101 | G10: =SUM(D10:F10) -> 1116598 | H10: 1743 | I10: 1925 | J10: 1915 | K10: 1925 | L10: =G10/(24*C10*0.57) -> 2632.9891 | M10: 417877 | N10: 93.66 | O10: 362.6 | P10: 1.1199 | Q10: 2.005 | R10: 2.2872 | S10: 101.75 | T10: 423.67 | U10: =MIN(J10,L10) -> 1915 | V10: =MIN(K10:L10) -> 1925 | W10: =D10*P10 -> 371809.04 | X10: =E10*Q10 -> 1416522.5 | Y10: =F10*R10 -> 178632.61 | Z10: =S10*V10 -> 195868.75 | AA10: =T10*U10 -> 811328.05 | AB10: =SUM(W10:AA10) -> 2974160.9 | AC10: =IF(N10<95,ROUND((3/5)*((95/N10)-1),3), ROUND((1/4)*(1-(90/N10)),3)) -> 0.009 | AD10: =(AB10+O10)*AC10 -> 26770.712 | AE10: =SUM(O10,AB10,AD10) -> 3001294.2 | AF10: =AE10*0.16 -> 480207.08 | AG10: =AE10*0.08 -> 240103.54 | AH10: =AE10+AF10+AG10 -> 3721604.8 | AI10: 3721605.6 | AJ10: NET MET | AK10: =AK22 -> 243 | AL10: =AL22 -> 457 | AM10: =AM22 -> 44 | AN10: =AN22 -> 48 | AO10: =AO22 -> 324 | AP10: =SUM(AN10:AO10) -> 372 | AQ10: =D10*AN10/AK10 -> 65580.642 | AR10: =E10*AO10/AL10 -> 500884.86 | AS10: =SUM(AQ10,AR10) -> 566465.5 | AT10: =AQ10/AS10 -> 0.11577164 | AU10: =AR10/AS10 -> 0.88422836 | AV10: =AS10/G10 -> 0.50731373 | AW10: 6.5503 | AX10: 0.85 | AY10: 0.62 | AZ10: =G10/(C10*AW10*AX10) -> 6469.2664 | BA10: =ROUNDUP(AZ10/AY10,0) -> 10435 | BB10: =E10/(C10*AW10*AX10) -> 4093.2407 | BC10: =ROUNDUP(BB10/AY10,0) -> 6603 | BD10: =AS10/(C10*AW10*AX10) -> 3281.9477 | BE10: =ROUNDUP(BD10/AY10,0) -> 5294 | BF10: =4560*AY10 -> 2827.2 | BG10: =BF10*C10*AW10*AX10 -> 487975.87 | BH10: =BG10*AT10 -> 56493.768 | BI10: =BG10*AU10 -> 431482.1 | BJ10: =ROUNDUP(BG10-AS10,0) -> -78490 | BK10: =D10-BH10 -> 275508.23 | BL10: =E10-BI10 -> 275012.9 | BM10: =IF(BJ10<0,G10-BG10,G10-BG10+BJ10) -> 628622.13 | BN10: =IF(BJ10<0,BG10/G10,(BG10-BJ10)/G10) -> 0.43702019 | BO10: =BK10 -> 275508.23 | BP10: =BL10 -> 275012.9 | BQ10: =F10 -> 78101 | BR10: =SUM(BO10:BQ10) -> 628622.13 | BS10: =BR10/(24*C10*0.57) -> 1482.3197 | BT10: =N10 -> 93.66 | BU10: =O10 -> 362.6 | BV10: =P10 -> 1.1199 | BW10: =Q10 -> 2.005 | BX10: =R10 -> 2.2872 | BY10: =S10 -> 101.75 | BZ10: =T10 -> 423.67 | CA10: =BO10*BV10 -> 308541.67 | CB10: =BP10*BW10 -> 551400.87 | CC10: =BQ10*BX10 -> 178632.61 | CD10: =BS10*BY10 -> 150826.03 | CE10: =BS10*BZ10 -> 628014.38 | CF10: =SUM(CA10:CC10) -> 1038575.1 | CG10: =AC10 -> 0.009 | CH10: =AD10 -> 26770.712 | CI10: =SUM(BU10,CF10,CH10) -> 1065708.5 | CJ10: =CI10*0.16 -> 170513.35 | CK10: =CI10*0.08 -> 85256.677 | CL10: =SUM(CI10,CJ10,CK10) -> 1321478.5 | CM10: =AI10-CL10 -> 2400127.1
A11: 45535 | B11: 45565 | C11: =B11-A11 -> 30 | D11: 330471 | E11: 633961 | F11: 69105 | G11: =SUM(D11:F11) -> 1033537 | H11: 1625 | I11: 1867 | J11: 1858 | K11: 1867 | L11: =G11/(24*C11*0.57) -> 2518.365 | M11: 383440 | N11: 93.76 | O11: 362.6 | P11: 1.1199 | Q11: 2.0051 | R11: 2.2873 | S11: 101.75 | T11: 423.69 | U11: =MIN(J11,L11) -> 1858 | V11: =MIN(K11:L11) -> 1867 | W11: =D11*P11 -> 370094.47 | X11: =E11*Q11 -> 1271155.2 | Y11: =F11*R11 -> 158063.87 | Z11: =S11*V11 -> 189967.25 | AA11: =T11*U11 -> 787216.02 | AB11: =SUM(W11:AA11) -> 2776496.8 | AC11: =IF(N11<95,ROUND((3/5)*((95/N11)-1),3), ROUND((1/4)*(1-(90/N11)),3)) -> 0.008 | AD11: =(AB11+O11)*AC11 -> 22214.875 | AE11: =SUM(O11,AB11,AD11) -> 2799074.3 | AF11: =AE11*0.16 -> 447851.89 | AG11: =AE11*0.08 -> 223925.94 | AH11: =AE11+AF11+AG11 -> 3470852.1 | AI11: 3470852.7 | AJ11: NET MET | AK11: =AK23 -> 249 | AL11: =AL23 -> 429 | AM11: =AM23 -> 42 | AN11: =AN23 -> 60 | AO11: =AO23 -> 300 | AP11: =SUM(AN11:AO11) -> 360 | AQ11: =D11*AN11/AK11 -> 79631.566 | AR11: =E11*AO11/AL11 -> 443329.37 | AS11: =SUM(AQ11,AR11) -> 522960.94 | AT11: =AQ11/AS11 -> 0.15227058 | AU11: =AR11/AS11 -> 0.84772942 | AV11: =AS11/G11 -> 0.5059915 | AW11: 5.3508 | AX11: 0.85 | AY11: 0.62 | AZ11: =G11/(C11*AW11*AX11) -> 7574.7295 | BA11: =ROUNDUP(AZ11/AY11,0) -> 12218 | BB11: =E11/(C11*AW11*AX11) -> 4646.2614 | BC11: =ROUNDUP(BB11/AY11,0) -> 7494 | BD11: =AS11/(C11*AW11*AX11) -> 3832.7488 | BE11: =ROUNDUP(BD11/AY11,0) -> 6182 | BF11: =4560*AY11 -> 2827.2 | BG11: =BF11*C11*AW11*AX11 -> 385758.43 | BH11: =BG11*AT11 -> 58739.661 | BI11: =BG11*AU11 -> 327018.77 | BJ11: =ROUNDUP(BG11-AS11,0) -> -137203 | BK11: =D11-BH11 -> 271731.34 | BL11: =E11-BI11 -> 306942.23 | BM11: =IF(BJ11<0,G11-BG11,G11-BG11+BJ11) -> 647778.57 | BN11: =IF(BJ11<0,BG11/G11,(BG11-BJ11)/G11) -> 0.37324105 | BO11: =BK11 -> 271731.34 | BP11: =BL11 -> 306942.23 | BQ11: =F11 -> 69105 | BR11: =SUM(BO11:BQ11) -> 647778.57 | BS11: =BR11/(24*C11*0.57) -> 1578.4078 | BT11: =N11 -> 93.76 | BU11: =O11 -> 362.6 | BV11: =P11 -> 1.1199 | BW11: =Q11 -> 2.0051 | BX11: =R11 -> 2.2873 | BY11: =S11 -> 101.75 | BZ11: =T11 -> 423.69 | CA11: =BO11*BV11 -> 304311.93 | CB11: =BP11*BW11 -> 615449.86 | CC11: =BQ11*BX11 -> 158063.87 | CD11: =BS11*BY11 -> 160602.99 | CE11: =BS11*BZ11 -> 668755.6 | CF11: =SUM(CA11:CC11) -> 1077825.7 | CG11: =AC11 -> 0.008 | CH11: =AD11 -> 22214.875 | CI11: =SUM(BU11,CF11,CH11) -> 1100403.1 | CJ11: =CI11*0.16 -> 176064.5 | CK11: =CI11*0.08 -> 88032.25 | CL11: =SUM(CI11,CJ11,CK11) -> 1364499.9 | CM11: =AI11-CL11 -> 2106352.8
A12: 45565 | B12: 45596 | C12: =B12-A12 -> 31 | D12: 321208 | E12: 640990 | F12: 87420 | G12: =SUM(D12:F12) -> 1049618 | H12: 1538 | I12: 1713 | J12: 1744 | K12: 1848 | L12: =G12/(24*C12*0.57) -> 2475.0472 | M12: 383597 | N12: 94.1 | O12: 362.6 | P12: 1.12 | Q12: 2.0052 | R12: 2.2874 | S12: 101.75 | T12: 423.7 | U12: =MIN(J12,L12) -> 1744 | V12: =MIN(K12:L12) -> 1848 | W12: =D12*P12 -> 359752.96 | X12: =E12*Q12 -> 1285313.1 | Y12: =F12*R12 -> 199964.51 | Z12: =S12*V12 -> 188034 | AA12: =T12*U12 -> 738932.8 | AB12: =SUM(W12:AA12) -> 2771997.4 | AC12: =IF(N12<95,ROUND((3/5)*((95/N12)-1),3), ROUND((1/4)*(1-(90/N12)),3)) -> 0.006 | AD12: =(AB12+O12)*AC12 -> 16634.16 | AE12: =SUM(O12,AB12,AD12) -> 2788994.2 | AF12: =AE12*0.16 -> 446239.07 | AG12: =AE12*0.08 -> 223119.53 | AH12: =AE12+AF12+AG12 -> 3458352.8 | AI12: 3505262.8 | AJ12: NET MET | AK12: =SUM(Hoja2!O277:O307) -> 241 | AL12: =SUM(Hoja2!P277:P307) -> 449 | AM12: =SUM(Hoja2!Q277:Q307) -> 54 | AN12: =SUM(Hoja2!R277:R307) -> 48 | AO12: =SUM(Hoja2!S277:S307) -> 324 | AP12: =SUM(AN12:AO12) -> 372 | AQ12: =D12*AN12/AK12 -> 63975.037 | AR12: =E12*AO12/AL12 -> 462540.67 | AS12: =SUM(AQ12,AR12) -> 526515.71 | AT12: =AQ12/AS12 -> 0.12150642 | AU12: =AR12/AS12 -> 0.87849358 | AV12: =AS12/G12 -> 0.50162603 | AW12: 5.6393 | AX12: 0.85 | AY12: 0.62 | AZ12: =G12/(C12*AW12*AX12) -> 7063.5895 | BA12: =ROUNDUP(AZ12/AY12,0) -> 11393 | BB12: =E12/(C12*AW12*AX12) -> 4313.6553 | BC12: =ROUNDUP(BB12/AY12,0) -> 6958 | BD12: =AS12/(C12*AW12*AX12) -> 3543.2803 | BE12: =ROUNDUP(BD12/AY12,0) -> 5715 | BF12: =4560*AY12 -> 2827.2 | BG12: =BF12*C12*AW12*AX12 -> 420109.35 | BH12: =BG12*AT12 -> 51045.983 | BI12: =BG12*AU12 -> 369063.37 | BJ12: =ROUNDUP(BG12-AS12,0) -> -106407 | BK12: =D12-BH12 -> 270162.02 | BL12: =E12-BI12 -> 271926.63 | BM12: =IF(BJ12<0,G12-BG12,G12-BG12+BJ12) -> 629508.65 | BN12: =IF(BJ12<0,BG12/G12,(BG12-BJ12)/G12) -> 0.40024976 | BO12: =BK12 -> 270162.02 | BP12: =BL12 -> 271926.63 | BQ12: =F12 -> 87420 | BR12: =SUM(BO12:BQ12) -> 629508.65 | BS12: =BR12/(24*C12*0.57) -> 1484.4101 | BT12: =N12 -> 94.1 | BU12: =O12 -> 362.6 | BV12: =P12 -> 1.12 | BW12: =Q12 -> 2.0052 | BX12: =R12 -> 2.2874 | BY12: =S12 -> 101.75 | BZ12: =T12 -> 423.7 | CA12: =BO12*BV12 -> 302581.46 | CB12: =BP12*BW12 -> 545267.28 | CC12: =BQ12*BX12 -> 199964.51 | CD12: =BS12*BY12 -> 151038.73 | CE12: =BS12*BZ12 -> 628944.57 | CF12: =SUM(CA12:CC12) -> 1047813.2 | CG12: =AC12 -> 0.006 | CH12: =AD12 -> 16634.16 | CI12: =SUM(BU12,CF12,CH12) -> 1064810 | CJ12: =CI12*0.16 -> 170369.6 | CK12: =CI12*0.08 -> 85184.8 | CL12: =SUM(CI12,CJ12,CK12) -> 1320364.4 | CM12: =AI12-CL12 -> 2184898.4
A13: 45596 | B13: 45626 | C13: =B13-A13 -> 30 | D13: 317744 | E13: 547998 | F13: 149661 | G13: =SUM(D13:F13) -> 1015403 | H13: 1778 | I13: 1809 | J13: 1807 | K13: 1809 | L13: =G13/(24*C13*0.57) -> 2474.1788 | M13: 362838 | N13: 94.17 | O13: 362.6 | P13: 1.1199 | Q13: 2.0051 | R13: 2.2873 | S13: 101.75 | T13: 423.69 | U13: =MIN(J13,L13) -> 1807 | V13: =MIN(K13:L13) -> 1809 | W13: =D13*P13 -> 355841.51 | X13: =E13*Q13 -> 1098790.8 | Y13: =F13*R13 -> 342319.61 | Z13: =S13*V13 -> 184065.75 | AA13: =T13*U13 -> 765607.83 | AB13: =SUM(W13:AA13) -> 2746625.5 | AC13: =IF(N13<95,ROUND((3/5)*((95/N13)-1),3), ROUND((1/4)*(1-(90/N13)),3)) -> 0.005 | AD13: =(AB13+O13)*AC13 -> 13734.94 | AE13: =SUM(O13,AB13,AD13) -> 2760723 | AF13: =AE13*0.16 -> 441715.68 | AG13: =AE13*0.08 -> 220857.84 | AH13: =AE13+AF13+AG13 -> 3423296.5 | AI13: 3423297.4 | AJ13: NET MET | AK13: =SUM(Hoja2!O308:O337) -> 238 | AL13: =SUM(Hoja2!P308:P337) -> 388 | AM13: =SUM(Hoja2!Q308:Q337) -> 94 | AN13: =SUM(Hoja2!R308:R337) -> 53 | AO13: =SUM(Hoja2!S308:S337) -> 307 | AP13: =SUM(AN13:AO13) -> 360 | AQ13: =D13*AN13/AK13 -> 70758.118 | AR13: =E13*AO13/AL13 -> 433596.36 | AS13: =SUM(AQ13,AR13) -> 504354.47 | AT13: =AQ13/AS13 -> 0.14029442 | AU13: =AR13/AS13 -> 0.85970558 | AV13: =AS13/G13 -> 0.49670375 | AW13: 5.2598 | AX13: 0.85 | AY13: 0.62 | AZ13: =G13/(C13*AW13*AX13) -> 7570.5779 | BA13: =ROUNDUP(AZ13/AY13,0) -> 12211 | BB13: =E13/(C13*AW13*AX13) -> 4085.729 | BC13: =ROUNDUP(BB13/AY13,0) -> 6590 | BD13: =AS13/(C13*AW13*AX13) -> 3760.3344 | BE13: =ROUNDUP(BD13/AY13,0) -> 6066 | BF13: =4560*AY13 -> 2827.2 | BG13: =BF13*C13*AW13*AX13 -> 379197.92 | BH13: =BG13*AT13 -> 53199.351 | BI13: =BG13*AU13 -> 325998.57 | BJ13: =ROUNDUP(BG13-AS13,0) -> -125157 | BK13: =D13-BH13 -> 264544.65 | BL13: =E13-BI13 -> 221999.43 | BM13: =IF(BJ13<0,G13-BG13,G13-BG13+BJ13) -> 636205.08 | BN13: =IF(BJ13<0,BG13/G13,(BG13-BJ13)/G13) -> 0.37344573 | BO13: =BK13 -> 264544.65 | BP13: =BL13 -> 221999.43 | BQ13: =F13 -> 149661 | BR13: =SUM(BO13:BQ13) -> 636205.08 | BS13: =BR13/(24*C13*0.57) -> 1550.2073 | BT13: =N13 -> 94.17 | BU13: =O13 -> 362.6 | BV13: =P13 -> 1.1199 | BW13: =Q13 -> 2.0051 | BX13: =R13 -> 2.2873 | BY13: =S13 -> 101.75 | BZ13: =T13 -> 423.69 | CA13: =BO13*BV13 -> 296263.55 | CB13: =BP13*BW13 -> 445131.07 | CC13: =BQ13*BX13 -> 342319.61 | CD13: =BS13*BY13 -> 157733.59 | CE13: =BS13*BZ13 -> 656807.34 | CF13: =SUM(CA13:CC13) -> 1083714.2 | CG13: =AC13 -> 0.005 | CH13: =AD13 -> 13734.94 | CI13: =SUM(BU13,CF13,CH13) -> 1097811.8 | CJ13: =CI13*0.16 -> 175649.88 | CK13: =CI13*0.08 -> 87824.941 | CL13: =SUM(CI13,CJ13,CK13) -> 1361286.6 | CM13: =AI13-CL13 -> 2062010.8
A14: 45626 | B14: 45657 | C14: =B14-A14 -> 31 | D14: 266857 | E14: 421137 | F14: 115374 | G14: =SUM(D14:F14) -> 803368 | H14: 1705 | I14: 1860 | J14: 1769 | K14: 1860 | L14: =G14/(24*C14*0.57) -> 1894.3784 | M14: 282886 | N14: 94.32 | O14: 362.6 | P14: 1.1044 | Q14: 1.9748 | R14: 2.2524 | S14: 101.75 | T14: 416.63 | U14: =MIN(J14,L14) -> 1769 | V14: =MIN(K14:L14) -> 1860 | W14: =D14*P14 -> 294716.87 | X14: =E14*Q14 -> 831661.35 | Y14: =F14*R14 -> 259868.4 | Z14: =S14*V14 -> 189255 | AA14: =T14*U14 -> 737018.47 | AB14: =SUM(W14:AA14) -> 2312520.1 | AC14: =IF(N14<95,ROUND((3/5)*((95/N14)-1),3), ROUND((1/4)*(1-(90/N14)),3)) -> 0.004 | AD14: =(AB14+O14)*AC14 -> 9251.5307 | AE14: =SUM(O14,AB14,AD14) -> 2322134.2 | AF14: =AE14*0.16 -> 371541.47 | AG14: =AE14*0.08 -> 185770.74 | AH14: =AE14+AF14+AG14 -> 2879446.4 | AI14: 2879446.8 | AJ14: NET MET | AK14: =SUM(Hoja2!O338:O368) -> 254 | AL14: =SUM(Hoja2!P338:P368) -> 394 | AM14: =SUM(Hoja2!Q338:Q368) -> 96 | AN14: =SUM(Hoja2!R338:R368) -> 64 | AO14: =SUM(Hoja2!S338:S368) -> 308 | AP14: =SUM(AN14:AO14) -> 372 | AQ14: =D14*AN14/AK14 -> 67239.559 | AR14: =E14*AO14/AL14 -> 329213.7 | AS14: =SUM(AQ14,AR14) -> 396453.25 | AT14: =AQ14/AS14 -> 0.16960274 | AU14: =AR14/AS14 -> 0.83039726 | AV14: =AS14/G14 -> 0.49348898 | AW14: 4.6351 | AX14: 0.85 | AY14: 0.62 | AZ14: =G14/(C14*AW14*AX14) -> 6577.7112 | BA14: =ROUNDUP(AZ14/AY14,0) -> 10610 | BB14: =E14/(C14*AW14*AX14) -> 3448.1303 | BC14: =ROUNDUP(BB14/AY14,0) -> 5562 | BD14: =AS14/(C14*AW14*AX14) -> 3246.028 | BE14: =ROUNDUP(BD14/AY14,0) -> 5236 | BF14: =4560*AY14 -> 2827.2 | BG14: =BF14*C14*AW14*AX14 -> 345299.75 | BH14: =BG14*AT14 -> 58563.784 | BI14: =BG14*AU14 -> 286735.96 | BJ14: =ROUNDUP(BG14-AS14,0) -> -51154 | BK14: =D14-BH14 -> 208293.22 | BL14: =E14-BI14 -> 134401.04 | BM14: =IF(BJ14<0,G14-BG14,G14-BG14+BJ14) -> 458068.25 | BN14: =IF(BJ14<0,BG14/G14,(BG14-BJ14)/G14) -> 0.42981516 | BO14: =BK14 -> 208293.22 | BP14: =BL14 -> 134401.04 | BQ14: =F14 -> 115374 | BR14: =SUM(BO14:BQ14) -> 458068.25 | BS14: =BR14/(24*C14*0.57) -> 1080.1459 | BT14: =N14 -> 94.32 | BU14: =O14 -> 362.6 | BV14: =P14 -> 1.1044 | BW14: =Q14 -> 1.9748 | BX14: =R14 -> 2.2524 | BY14: =S14 -> 101.75 | BZ14: =T14 -> 416.63 | CA14: =BO14*BV14 -> 230039.03 | CB14: =BP14*BW14 -> 265415.17 | CC14: =BQ14*BX14 -> 259868.4 | CD14: =BS14*BY14 -> 109904.84 | CE14: =BS14*BZ14 -> 450021.17 | CF14: =SUM(CA14:CC14) -> 755322.59 | CG14: =AC14 -> 0.004 | CH14: =AD14 -> 9251.5307 | CI14: =SUM(BU14,CF14,CH14) -> 764936.72 | CJ14: =CI14*0.16 -> 122389.88 | CK14: =CI14*0.08 -> 61194.938 | CL14: =SUM(CI14,CJ14,CK14) -> 948521.54 | CM14: =AI14-CL14 -> 1930925.3
A15: 45657 | B15: 45688 | C15: =B15-A15 -> 31 | D15: 290568 | E15: 539148 | F15: 150493 | G15: =SUM(D15:F15) -> 980209 | H15: 1774 | I15: 1856 | J15: 1753 | K15: 1856 | L15: =G15/(24*C15*0.57) -> 2311.3776 | M15: 336846 | N15: 94.57 | O15: 368.95 | P15: 1.119 | Q15: 1.9995 | R15: 2.2803 | S15: 102.05 | T15: 421.46 | U15: =MIN(J15,L15) -> 1753 | V15: =MIN(K15:L15) -> 1856 | W15: =D15*P15 -> 325145.59 | X15: =E15*Q15 -> 1078026.4 | Y15: =F15*R15 -> 343169.19 | Z15: =S15*V15 -> 189404.8 | AA15: =T15*U15 -> 738819.38 | AB15: =SUM(W15:AA15) -> 2674565.4 | AC15: =IF(N15<95,ROUND((3/5)*((95/N15)-1),3), ROUND((1/4)*(1-(90/N15)),3)) -> 0.003 | AD15: =(AB15+O15)*AC15 -> 8024.803 | AE15: =SUM(O15,AB15,AD15) -> 2682959.1 | AF15: =AE15*0.16 -> 429273.46 | AG15: =AE15*0.08 -> 214636.73 | AH15: =AE15+AF15+AG15 -> 3326869.3 | AI15: 3326870.1 | AJ15: NET MET | AK15: =SUM(Hoja2!O369,Hoja2!O5:O34) -> 242 | AL15: =SUM(Hoja2!P369,Hoja2!P5:P34) -> 402 | AM15: =SUM(Hoja2!Q369,Hoja2!Q5:Q34) -> 100 | AN15: =SUM(Hoja2!R369,Hoja2!R5:R34) -> 52 | AO15: =SUM(Hoja2!S369,Hoja2!S5:S34) -> 320 | AP15: =SUM(AN15:AO15) -> 372 | AQ15: =D15*AN15/AK15 -> 62436.099 | AR15: =E15*AO15/AL15 -> 429172.54 | AS15: =SUM(AQ15,AR15) -> 491608.64 | AT15: =AQ15/AS15 -> 0.12700367 | AU15: =AR15/AS15 -> 0.87299633 | AV15: =AS15/G15 -> 0.50153451 | AW15: 4.5859 | AX15: 0.85 | AY15: 0.62 | AZ15: =G15/(C15*AW15*AX15) -> 8111.73 | BA15: =ROUNDUP(AZ15/AY15,0) -> 13084 | BB15: =E15/(C15*AW15*AX15) -> 4461.725 | BC15: =ROUNDUP(BB15/AY15,0) -> 7197 | BD15: =AS15/(C15*AW15*AX15) -> 4068.3125 | BE15: =ROUNDUP(BD15/AY15,0) -> 6562 | BF15: =4560*AY15 -> 2827.2 | BG15: =BF15*C15*AW15*AX15 -> 341634.51 | BH15: =BG15*AT15 -> 43388.835 | BI15: =BG15*AU15 -> 298245.67 | BJ15: =ROUNDUP(BG15-AS15,0) -> -149975 | BK15: =D15-BH15 -> 247179.16 | BL15: =E15-BI15 -> 240902.33 | BM15: =IF(BJ15<0,G15-BG15,G15-BG15+BJ15) -> 638574.49 | BN15: =IF(BJ15<0,BG15/G15,(BG15-BJ15)/G15) -> 0.34853231 | BO15: =BK15 -> 247179.16 | BP15: =BL15 -> 240902.33 | BQ15: =F15 -> 150493 | BR15: =SUM(BO15:BQ15) -> 638574.49 | BS15: =BR15/(24*C15*0.57) -> 1505.7878 | BT15: =N15 -> 94.57 | BU15: =O15 -> 368.95 | BV15: =P15 -> 1.119 | BW15: =Q15 -> 1.9995 | BX15: =R15 -> 2.2803 | BY15: =S15 -> 102.05 | BZ15: =T15 -> 421.46 | CA15: =BO15*BV15 -> 276593.49 | CB15: =BP15*BW15 -> 481684.2 | CC15: =BQ15*BX15 -> 343169.19 | CD15: =BS15*BY15 -> 153665.65 | CE15: =BS15*BZ15 -> 634629.33 | CF15: =SUM(CA15:CC15) -> 1101446.9 | CG15: =AC15 -> 0.003 | CH15: =AD15 -> 8024.803 | CI15: =SUM(BU15,CF15,CH15) -> 1109840.6 | CJ15: =CI15*0.16 -> 177574.5 | CK15: =CI15*0.08 -> 88787.25 | CL15: =SUM(CI15,CJ15,CK15) -> 1376202.4 | CM15: =AI15-CL15 -> 1950667.7
A16: 45688 | B16: 45716 | C16: =B16-A16 -> 28 | D16: 281455 | E16: 480769 | F16: 137541 | G16: =SUM(D16:F16) -> 899765 | H16: 1695 | I16: 1781 | J16: 1798 | K16: 1798 | L16: =G16/(24*C16*0.57) -> 2349.0105 | M16: 320568 | N16: 94.2 | O16: 368.95 | P16: 1.1205 | Q16: 2.0024 | R16: 2.2836 | S16: 102.05 | T16: 422.13 | U16: =MIN(J16,L16) -> 1798 | V16: =MIN(K16:L16) -> 1798 | W16: =D16*P16 -> 315370.33 | X16: =E16*Q16 -> 962691.85 | Y16: =F16*R16 -> 314088.63 | Z16: =S16*V16 -> 183485.9 | AA16: =T16*U16 -> 758989.74 | AB16: =SUM(W16:AA16) -> 2534626.4 | AC16: =IF(N16<95,ROUND((3/5)*((95/N16)-1),3), ROUND((1/4)*(1-(90/N16)),3)) -> 0.005 | AD16: =(AB16+O16)*AC16 -> 12674.977 | AE16: =SUM(O16,AB16,AD16) -> 2547670.4 | AF16: =AE16*0.16 -> 407627.26 | AG16: =AE16*0.08 -> 203813.63 | AH16: =AE16+AF16+AG16 -> 3159111.3 | AI16: 3159111.4 | AJ16: NET MET | AK16: =SUM(Hoja2!O35:O62) -> 224 | AL16: =SUM(Hoja2!P35:P62) -> 360 | AM16: =SUM(Hoja2!Q35:Q62) -> 88 | AN16: =SUM(Hoja2!R35:R62) -> 52 | AO16: =SUM(Hoja2!S35:S62) -> 284 | AP16: =SUM(AN16:AO16) -> 336 | AQ16: =D16*AN16/AK16 -> 65337.768 | AR16: =E16*AO16/AL16 -> 379273.32 | AS16: =SUM(AQ16,AR16) -> 444611.09 | AT16: =AQ16/AS16 -> 0.14695488 | AU16: =AR16/AS16 -> 0.85304512 | AV16: =AS16/G16 -> 0.49414135 | AW16: 6.0036 | AX16: 0.85 | AY16: 0.62 | AZ16: =G16/(C16*AW16*AX16) -> 6297.0971 | BA16: =ROUNDUP(AZ16/AY16,0) -> 10157 | BB16: =E16/(C16*AW16*AX16) -> 3364.7109 | BC16: =ROUNDUP(BB16/AY16,0) -> 5427 | BD16: =AS16/(C16*AW16*AX16) -> 3111.656 | BE16: =ROUNDUP(BD16/AY16,0) -> 5019 | BF16: =4560*AY16 -> 2827.2 | BG16: =BF16*C16*AW16*AX16 -> 403966.39 | BH16: =BG16*AT16 -> 59364.832 | BI16: =BG16*AU16 -> 344601.56 | BJ16: =ROUNDUP(BG16-AS16,0) -> -40645 | BK16: =D16-BH16 -> 222090.17 | BL16: =E16-BI16 -> 136167.44 | BM16: =IF(BJ16<0,G16-BG16,G16-BG16+BJ16) -> 495798.61 | BN16: =IF(BJ16<0,BG16/G16,(BG16-BJ16)/G16) -> 0.44896878 | BO16: =BK16 -> 222090.17 | BP16: =BL16 -> 136167.44 | BQ16: =F16 -> 137541 | BR16: =SUM(BO16:BQ16) -> 495798.61 | BS16: =BR16/(24*C16*0.57) -> 1294.3781 | BT16: =N16 -> 94.2 | BU16: =O16 -> 368.95 | BV16: =P16 -> 1.1205 | BW16: =Q16 -> 2.0024 | BX16: =R16 -> 2.2836 | BY16: =S16 -> 102.05 | BZ16: =T16 -> 422.13 | CA16: =BO16*BV16 -> 248852.03 | CB16: =BP16*BW16 -> 272661.68 | CC16: =BQ16*BX16 -> 314088.63 | CD16: =BS16*BY16 -> 132091.29 | CE16: =BS16*BZ16 -> 546395.85 | CF16: =SUM(CA16:CC16) -> 835602.34 | CG16: =AC16 -> 0.005 | CH16: =AD16 -> 12674.977 | CI16: =SUM(BU16,CF16,CH16) -> 848646.26 | CJ16: =CI16*0.16 -> 135783.4 | CK16: =CI16*0.08 -> 67891.701 | CL16: =SUM(CI16,CJ16,CK16) -> 1052321.4 | CM16: =AI16-CL16 -> 2106790
A17: 45716 | B17: 45747 | C17: =B17-A17 -> 31 | D17: 315921 | E17: 524576 | F17: 145990 | G17: =SUM(D17:F17) -> 986487 | H17: 1692 | I17: 1805 | J17: 1811 | K17: 1811 | L17: =G17/(24*C17*0.57) -> 2326.1814 | M17: 364109 | N17: 93.81 | O17: 368.95 | P17: 1.1209 | Q17: 2.0032 | R17: 2.2845 | S17: 102.05 | T17: 422.31 | U17: =MIN(J17,L17) -> 1811 | V17: =MIN(K17:L17) -> 1811 | W17: =D17*P17 -> 354115.85 | X17: =E17*Q17 -> 1050830.6 | Y17: =F17*R17 -> 333514.15 | Z17: =S17*V17 -> 184812.55 | AA17: =T17*U17 -> 764803.41 | AB17: =SUM(W17:AA17) -> 2688076.6 | AC17: =IF(N17<95,ROUND((3/5)*((95/N17)-1),3), ROUND((1/4)*(1-(90/N17)),3)) -> 0.008 | AD17: =(AB17+O17)*AC17 -> 21507.564 | AE17: =SUM(O17,AB17,AD17) -> 2709953.1 | AF17: =AE17*0.16 -> 433592.5 | AG17: =AE17*0.08 -> 216796.25 | AH17: =AE17+AF17+AG17 -> 3360341.9 | AI17: 3360342.2 | AJ17: NET MET | AK17: =SUM(Hoja2!O63:O93) -> 256 | AL17: =SUM(Hoja2!P63:P93) -> 394 | AM17: =SUM(Hoja2!Q63:Q93) -> 94 | AN17: =SUM(Hoja2!R63:R93) -> 65 | AO17: =SUM(Hoja2!S63:S93) -> 307 | AP17: =SUM(AN17:AO17) -> 372 | AQ17: =D17*AN17/AK17 -> 80214.316 | AR17: =E17*AO17/AL17 -> 408743.23 | AS17: =SUM(AQ17,AR17) -> 488957.54 | AT17: =AQ17/AS17 -> 0.1640517 | AU17: =AR17/AS17 -> 0.8359483 | AV17: =AS17/G17 -> 0.49565534 | AW17: 7.381 | AX17: 0.85 | AY17: 0.62 | AZ17: =G17/(C17*AW17*AX17) -> 5072.1903 | BA17: =ROUNDUP(AZ17/AY17,0) -> 8181 | BB17: =E17/(C17*AW17*AX17) -> 2697.1965 | BC17: =ROUNDUP(BB17/AY17,0) -> 4351 | BD17: =AS17/(C17*AW17*AX17) -> 2514.0582 | BE17: =ROUNDUP(BD17/AY17,0) -> 4055 | BF17: =4560*AY17 -> 2827.2 | BG17: =BF17*C17*AW17*AX17 -> 549860.29 | BH17: =BG17*AT17 -> 90205.515 | BI17: =BG17*AU17 -> 459654.77 | BJ17: =ROUNDUP(BG17-AS17,0) -> 60903 | BK17: =D17-BH17 -> 225715.48 | BL17: =E17-BI17 -> 64921.225 | BM17: =IF(BJ17<0,G17-BG17,G17-BG17+BJ17) -> 497529.71 | BN17: =IF(BJ17<0,BG17/G17,(BG17-BJ17)/G17) -> 0.49565508 | BO17: =BK17 -> 225715.48 | BP17: =BL17 -> 64921.225 | BQ17: =F17 -> 145990 | BR17: =SUM(BO17:BQ17) -> 436626.71 | BS17: =BR17/(24*C17*0.57) -> 1029.5857 | BT17: =N17 -> 93.81 | BU17: =O17 -> 368.95 | BV17: =P17 -> 1.1209 | BW17: =Q17 -> 2.0032 | BX17: =R17 -> 2.2845 | BY17: =S17 -> 102.05 | BZ17: =T17 -> 422.31 | CA17: =BO17*BV17 -> 253004.49 | CB17: =BP17*BW17 -> 130050.2 | CC17: =BQ17*BX17 -> 333514.15 | CD17: =BS17*BY17 -> 105069.22 | CE17: =BS17*BZ17 -> 434804.34 | CF17: =SUM(CA17:CC17) -> 716568.84 | CG17: =AC17 -> 0.008 | CH17: =AD17 -> 21507.564 | CI17: =SUM(BU17,CF17,CH17) -> 738445.35 | CJ17: =CI17*0.16 -> 118151.26 | CK17: =CI17*0.08 -> 59075.628 | CL17: =SUM(CI17,CJ17,CK17) -> 915672.24 | CM17: =AI17-CL17 -> 2444670
A18: 45747 | B18: 45777 | C18: =B18-A18 -> 30 | D18: 229333 | E18: 467943 | F18: 56501 | G18: =SUM(D18:F18) -> 753777 | H18: 1759 | I18: 1539 | J18: 1810 | K18: 2199 | L18: =G18/(24*C18*0.57) -> 1836.6886 | M18: 378000 | N18: 93.14 | O18: 368.95 | P18: 1.1209 | Q18: 2.0032 | R18: 2.2845 | S18: 102.05 | T18: 422.31 | U18: =MIN(J18,L18) -> 1810 | V18: =MIN(K18:L18) -> 1836.6886 | W18: =D18*P18 -> 257059.36 | X18: =E18*Q18 -> 937383.42 | Y18: =F18*R18 -> 129076.53 | Z18: =S18*V18 -> 187434.07 | AA18: =T18*U18 -> 764381.1 | AB18: =SUM(W18:AA18) -> 2275334.5 | AC18: =IF(N18<95,ROUND((3/5)*((95/N18)-1),3), ROUND((1/4)*(1-(90/N18)),3)) -> 0.012 | AD18: =(AB18+O18)*AC18 -> 27308.441 | AE18: =SUM(O18,AB18,AD18) -> 2303011.9 | AF18: =AE18*0.16 -> 368481.9 | AG18: =AE18*0.08 -> 184240.95 | AH18: =AE18+AF18+AG18 -> 2855734.7 | AI18: 3159586.6 | AJ18: NET MET | AK18: =SUM(Hoja2!O94:O123) -> 237 | AL18: =SUM(Hoja2!P94:P123) -> 427 | AM18: =SUM(Hoja2!Q94:Q123) -> 56 | AN18: =SUM(Hoja2!R94:R123) -> 49 | AO18: =SUM(Hoja2!S94:S123) -> 311 | AP18: =SUM(AN18:AO18) -> 360 | AQ18: =D18*AN18/AK18 -> 47414.84 | AR18: =E18*AO18/AL18 -> 340820.31 | AS18: =SUM(AQ18,AR18) -> 388235.15 | AT18: =AQ18/AS18 -> 0.12212918 | AU18: =AR18/AS18 -> 0.87787082 | AV18: =AS18/G18 -> 0.51505306 | AW18: 7.8588 | AX18: 0.85 | AY18: 0.62 | AZ18: =G18/(C18*AW18*AX18) -> 3761.3735 | BA18: =ROUNDUP(AZ18/AY18,0) -> 6067 | BB18: =E18/(C18*AW18*AX18) -> 2335.0519 | BC18: =ROUNDUP(BB18/AY18,0) -> 3767 | BD18: =AS18/(C18*AW18*AX18) -> 1937.307 | BE18: =ROUNDUP(BD18/AY18,0) -> 3125 | BF18: =4560*AY18 -> 2827.2 | BG18: =BF18*C18*AW18*AX18 -> 566569.18 | BH18: =BG18*AT18 -> 69194.628 | BI18: =BG18*AU18 -> 497374.56 | BJ18: =ROUNDUP(BG18-AS18,0) -> 178335 | BK18: =D18-BH18 -> 160138.37 | BL18: =E18-BI18 -> -29431.555 | BM18: =IF(BJ18<0,G18-BG18,G18-BG18+BJ18) -> 365542.82 | BN18: =IF(BJ18<0,BG18/G18,(BG18-BJ18)/G18) -> 0.51505178 | BO18: =BK18 -> 160138.37 | BP18: =BL18 -> -29431.555 | BQ18: =F18 -> 56501 | BR18: =SUM(BO18:BQ18) -> 187207.82 | BS18: =BR18/(24*C18*0.57) -> 456.1594 | BT18: =N18 -> 93.14 | BU18: =O18 -> 368.95 | BV18: =P18 -> 1.1209 | BW18: =Q18 -> 2.0032 | BX18: =R18 -> 2.2845 | BY18: =S18 -> 102.05 | BZ18: =T18 -> 422.31 | CA18: =BO18*BV18 -> 179499.1 | CB18: =BP18*BW18 -> -58957.292 | CC18: =BQ18*BX18 -> 129076.53 | CD18: =BS18*BY18 -> 46551.066 | CE18: =BS18*BZ18 -> 192640.67 | CF18: =SUM(CA18:CC18) -> 249618.34 | CG18: =AC18 -> 0.012 | CH18: =AD18 -> 27308.441 | CI18: =SUM(BU18,CF18,CH18) -> 277295.73 | CJ18: =CI18*0.16 -> 44367.318 | CK18: =CI18*0.08 -> 22183.659 | CL18: =SUM(CI18,CJ18,CK18) -> 343846.71 | CM18: =AI18-CL18 -> 2815739.9
A19: 45777 | B19: 45808 | C19: =B19-A19 -> 31 | D19: 314014 | E19: 631629 | F19: 71617 | G19: =SUM(D19:F19) -> 1017260 | H19: 1629 | I19: 1850 | J19: 1830 | K19: 1850 | L19: =G19/(24*C19*0.57) -> 2398.7455 | M19: 389248 | N19: 93.4 | O19: 368.95 | P19: 1.1209 | Q19: 2.0032 | R19: 2.2845 | S19: 102.05 | T19: 422.31 | U19: =MIN(J19,L19) -> 1830 | V19: =MIN(K19:L19) -> 1850 | W19: =D19*P19 -> 351978.29 | X19: =E19*Q19 -> 1265279.2 | Y19: =F19*R19 -> 163609.04 | Z19: =S19*V19 -> 188792.5 | AA19: =T19*U19 -> 772827.3 | AB19: =SUM(W19:AA19) -> 2742486.3 | AC19: =IF(N19<95,ROUND((3/5)*((95/N19)-1),3), ROUND((1/4)*(1-(90/N19)),3)) -> 0.01 | AD19: =(AB19+O19)*AC19 -> 27428.553 | AE19: =SUM(O19,AB19,AD19) -> 2770283.8 | AF19: =AE19*0.16 -> 443245.42 | AG19: =AE19*0.08 -> 221622.71 | AH19: =AE19+AF19+AG19 -> 3435152 | AI19: 3435152.6 | AJ19: NET MET | AK19: =SUM(Hoja2!O124:O154) -> 242 | AL19: =SUM(Hoja2!P124:P154) -> 456 | AM19: =SUM(Hoja2!Q124:Q154) -> 46 | AN19: =SUM(Hoja2!R124:R154) -> 48 | AO19: =SUM(Hoja2!S124:S154) -> 324 | AP19: =SUM(AN19:AO19) -> 372 | AQ19: =D19*AN19/AK19 -> 62283.769 | AR19: =E19*AO19/AL19 -> 448789.03 | AS19: =SUM(AQ19,AR19) -> 511072.79 | AT19: =AQ19/AS19 -> 0.12186868 | AU19: =AR19/AS19 -> 0.87813132 | AV19: =AS19/G19 -> 0.50240135 | AW19: 7.4323 | AX19: 0.85 | AY19: 0.62 | AZ19: =G19/(C19*AW19*AX19) -> 5194.313 | BA19: =ROUNDUP(AZ19/AY19,0) -> 8378 | BB19: =E19/(C19*AW19*AX19) -> 3225.2116 | BC19: =ROUNDUP(BB19/AY19,0) -> 5202 | BD19: =AS19/(C19*AW19*AX19) -> 2609.6299 | BE19: =ROUNDUP(BD19/AY19,0) -> 4210 | BF19: =4560*AY19 -> 2827.2 | BG19: =BF19*C19*AW19*AX19 -> 553681.97 | BH19: =BG19*AT19 -> 67476.493 | BI19: =BG19*AU19 -> 486205.48 | BJ19: =ROUNDUP(BG19-AS19,0) -> 42610 | BK19: =D19-BH19 -> 246537.51 | BL19: =E19-BI19 -> 145423.52 | BM19: =IF(BJ19<0,G19-BG19,G19-BG19+BJ19) -> 506188.03 | BN19: =IF(BJ19<0,BG19/G19,(BG19-BJ19)/G19) -> 0.50240054 | BO19: =BK19 -> 246537.51 | BP19: =BL19 -> 145423.52 | BQ19: =F19 -> 71617 | BR19: =SUM(BO19:BQ19) -> 463578.03 | BS19: =BR19/(24*C19*0.57) -> 1093.1382 | BT19: =N19 -> 93.4 | BU19: =O19 -> 368.95 | BV19: =P19 -> 1.1209 | BW19: =Q19 -> 2.0032 | BX19: =R19 -> 2.2845 | BY19: =S19 -> 102.05 | BZ19: =T19 -> 422.31 | CA19: =BO19*BV19 -> 276343.89 | CB19: =BP19*BW19 -> 291312.4 | CC19: =BQ19*BX19 -> 163609.04 | CD19: =BS19*BY19 -> 111554.75 | CE19: =BS19*BZ19 -> 461643.17 | CF19: =SUM(CA19:CC19) -> 731265.33 | CG19: =AC19 -> 0.01 | CH19: =AD19 -> 27428.553 | CI19: =SUM(BU19,CF19,CH19) -> 759062.83 | CJ19: =CI19*0.16 -> 121450.05 | CK19: =CI19*0.08 -> 60725.026 | CL19: =SUM(CI19,CJ19,CK19) -> 941237.91 | CM19: =AI19-CL19 -> 2493914.7
A20: 45808 | B20: 45838 | C20: =B20-A20 -> 30 | D20: 309392 | E20: 617882 | F20: 69202 | G20: =SUM(D20:F20) -> 996476 | H20: 1593 | I20: 1861 | J20: 1859 | K20: 1861 | L20: =G20/(24*C20*0.57) -> 2428.0604 | M20: 375229 | N20: 93.59 | O20: 368.95 | P20: 1.1429 | Q20: 2.0461 | R20: 2.3342 | S20: 102.05 | T20: 432.34 | U20: =MIN(J20,L20) -> 1859 | V20: =MIN(K20:L20) -> 1861 | W20: =D20*P20 -> 353604.12 | X20: =E20*Q20 -> 1264248.4 | Y20: =F20*R20 -> 161531.31 | Z20: =S20*V20 -> 189915.05 | AA20: =T20*U20 -> 803720.06 | AB20: =SUM(W20:AA20) -> 2773018.9 | AC20: =IF(N20<95,ROUND((3/5)*((95/N20)-1),3), ROUND((1/4)*(1-(90/N20)),3)) -> 0.009 | AD20: =(AB20+O20)*AC20 -> 24960.491 | AE20: =SUM(O20,AB20,AD20) -> 2798348.3 | AF20: =AE20*0.16 -> 447735.73 | AG20: =AE20*0.08 -> 223867.87 | AH20: =AE20+AF20+AG20 -> 3469951.9 | AI20: 3469952.6 | AJ20: NET MET | AK20: =SUM(Hoja2!O155:O184) -> 250 | AL20: =SUM(Hoja2!P155:P184) -> 430 | AM20: =SUM(Hoja2!Q155:Q184) -> 40 | AN20: =SUM(Hoja2!R155:R184) -> 60 | AO20: =SUM(Hoja2!S155:S184) -> 300 | AP20: =SUM(AN20:AO20) -> 360 | AQ20: =D20*AN20/AK20 -> 74254.08 | AR20: =E20*AO20/AL20 -> 431080.47 | AS20: =SUM(AQ20,AR20) -> 505334.55 | AT20: =AQ20/AS20 -> 0.14694044 | AU20: =AR20/AS20 -> 0.85305956 | AV20: =AS20/G20 -> 0.50712164 | AW20: 6.1452 | AX20: 0.85 | AY20: 0.62 | AZ20: =G20/(C20*AW20*AX20) -> 6359.0266 | BA20: =ROUNDUP(AZ20/AY20,0) -> 10257 | BB20: =E20/(C20*AW20*AX20) -> 3943.0233 | BC20: =ROUNDUP(BB20/AY20,0) -> 6360 | BD20: =AS20/(C20*AW20*AX20) -> 3224.8 | BE20: =ROUNDUP(BD20/AY20,0) -> 5202 | BF20: =4560*AY20 -> 2827.2 | BG20: =BF20*C20*AW20*AX20 -> 443029.59 | BH20: =BG20*AT20 -> 65098.963 | BI20: =BG20*AU20 -> 377930.63 | BJ20: =ROUNDUP(BG20-AS20,0) -> -62305 | BK20: =D20-BH20 -> 244293.04 | BL20: =E20-BI20 -> 239951.37 | BM20: =IF(BJ20<0,G20-BG20,G20-BG20+BJ20) -> 553446.41 | BN20: =IF(BJ20<0,BG20/G20,(BG20-BJ20)/G20) -> 0.44459635 | BO20: =BK20 -> 244293.04 | BP20: =BL20 -> 239951.37 | BQ20: =F20 -> 69202 | BR20: =SUM(BO20:BQ20) -> 553446.41 | BS20: =BR20/(24*C20*0.57) -> 1348.5536 | BT20: =N20 -> 93.59 | BU20: =O20 -> 368.95 | BV20: =P20 -> 1.1429 | BW20: =Q20 -> 2.0461 | BX20: =R20 -> 2.3342 | BY20: =S20 -> 102.05 | BZ20: =T20 -> 432.34 | CA20: =BO20*BV20 -> 279202.51 | CB20: =BP20*BW20 -> 490964.5 | CC20: =BQ20*BX20 -> 161531.31 | CD20: =BS20*BY20 -> 137619.9 | CE20: =BS20*BZ20 -> 583033.68 | CF20: =SUM(CA20:CC20) -> 931698.32 | CG20: =AC20 -> 0.009 | CH20: =AD20 -> 24960.491 | CI20: =SUM(BU20,CF20,CH20) -> 957027.76 | CJ20: =CI20*0.16 -> 153124.44 | CK20: =CI20*0.08 -> 76562.221 | CL20: =SUM(CI20,CJ20,CK20) -> 1186714.4 | CM20: =AI20-CL20 -> 2283238.1
A21: 45838 | B21: 45869 | C21: =B21-A21 -> 31 | D21: 292181 | E21: 637645 | F21: 73589 | G21: =SUM(D21:F21) -> 1003415 | H21: 1532 | I21: 1777 | J21: 1822 | K21: 1822 | L21: =G21/(24*C21*0.57) -> 2366.0984 | M21: 374983 | N21: 93.67 | O21: 368.95 | P21: 1.1572 | Q21: 2.0739 | R21: 2.3663 | S21: 102.05 | T21: 438.82 | U21: =MIN(J21,L21) -> 1822 | V21: =MIN(K21:L21) -> 1822 | W21: =D21*P21 -> 338111.85 | X21: =E21*Q21 -> 1322412 | Y21: =F21*R21 -> 174133.65 | Z21: =S21*V21 -> 185935.1 | AA21: =T21*U21 -> 799530.04 | AB21: =SUM(W21:AA21) -> 2820122.6 | AC21: =IF(N21<95,ROUND((3/5)*((95/N21)-1),3), ROUND((1/4)*(1-(90/N21)),3)) -> 0.009 | AD21: =(AB21+O21)*AC21 -> 25384.424 | AE21: =SUM(O21,AB21,AD21) -> 2845876 | AF21: =AE21*0.16 -> 455340.16 | AG21: =AE21*0.08 -> 227670.08 | AH21: =AE21+AF21+AG21 -> 3528886.2 | AI21: 3528886.8 | AJ21: NET MET | AK21: =SUM(Hoja2!O185:O215) -> 242 | AL21: =SUM(Hoja2!P185:P215) -> 456 | AM21: =SUM(Hoja2!Q185:Q215) -> 46 | AN21: =SUM(Hoja2!R185:R215) -> 48 | AO21: =SUM(Hoja2!S185:S215) -> 324 | AP21: =SUM(AN21:AO21) -> 372 | AQ21: =D21*AN21/AK21 -> 57953.256 | AR21: =E21*AO21/AL21 -> 453063.55 | AS21: =SUM(AQ21,AR21) -> 511016.81 | AT21: =AQ21/AS21 -> 0.11340773 | AU21: =AR21/AS21 -> 0.88659227 | AV21: =AS21/G21 -> 0.50927763 | AW21: 6.1498 | AX21: 0.85 | AY21: 0.62 | AZ21: =G21/(C21*AW21*AX21) -> 6192.1145 | BA21: =ROUNDUP(AZ21/AY21,0) -> 9988 | BB21: =E21/(C21*AW21*AX21) -> 3934.933 | BC21: =ROUNDUP(BB21/AY21,0) -> 6347 | BD21: =AS21/(C21*AW21*AX21) -> 3153.5054 | BE21: =ROUNDUP(BD21/AY21,0) -> 5087 | BF21: =4560*AY21 -> 2827.2 | BG21: =BF21*C21*AW21*AX21 -> 458139.93 | BH21: =BG21*AT21 -> 51956.609 | BI21: =BG21*AU21 -> 406183.32 | BJ21: =ROUNDUP(BG21-AS21,0) -> -52877 | BK21: =D21-BH21 -> 240224.39 | BL21: =E21-BI21 -> 231461.68 | BM21: =IF(BJ21<0,G21-BG21,G21-BG21+BJ21) -> 545275.07 | BN21: =IF(BJ21<0,BG21/G21,(BG21-BJ21)/G21) -> 0.45658071 | BO21: =BK21 -> 240224.39 | BP21: =BL21 -> 231461.68 | BQ21: =F21 -> 73589 | BR21: =SUM(BO21:BQ21) -> 545275.07 | BS21: =BR21/(24*C21*0.57) -> 1285.7835 | BT21: =N21 -> 93.67 | BU21: =O21 -> 368.95 | BV21: =P21 -> 1.1572 | BW21: =Q21 -> 2.0739 | BX21: =R21 -> 2.3663 | BY21: =S21 -> 102.05 | BZ21: =T21 -> 438.82 | CA21: =BO21*BV21 -> 277987.66 | CB21: =BP21*BW21 -> 480028.38 | CC21: =BQ21*BX21 -> 174133.65 | CD21: =BS21*BY21 -> 131214.21 | CE21: =BS21*BZ21 -> 564227.52 | CF21: =SUM(CA21:CC21) -> 932149.7 | CG21: =AC21 -> 0.009 | CH21: =AD21 -> 25384.424 | CI21: =SUM(BU21,CF21,CH21) -> 957903.07 | CJ21: =CI21*0.16 -> 153264.49 | CK21: =CI21*0.08 -> 76632.246 | CL21: =SUM(CI21,CJ21,CK21) -> 1187799.8 | CM21: =AI21-CL21 -> 2341087
A22: 45869 | B22: 45900 | C22: =B22-A22 -> 31 | D22: 312212 | E22: 636185 | F22: 68684 | G22: =SUM(D22:F22) -> 1017081 | H22: 1524 | I22: 1802 | J22: 1784 | K22: 1802 | L22: =G22/(24*C22*0.57) -> 2398.3234 | M22: 360110 | N22: 94.27 | O22: 368.95 | P22: 1.1585 | Q22: 2.0765 | R22: 2.3693 | S22: 102.05 | T22: 439.43 | U22: =MIN(J22,L22) -> 1784 | V22: =MIN(K22:L22) -> 1802 | W22: =D22*P22 -> 361697.6 | X22: =E22*Q22 -> 1321038.2 | Y22: =F22*R22 -> 162733 | Z22: =S22*V22 -> 183894.1 | AA22: =T22*U22 -> 783943.12 | AB22: =SUM(W22:AA22) -> 2813306 | AC22: =IF(N22<95,ROUND((3/5)*((95/N22)-1),3), ROUND((1/4)*(1-(90/N22)),3)) -> 0.005 | AD22: =(AB22+O22)*AC22 -> 14068.375 | AE22: =SUM(O22,AB22,AD22) -> 2827743.3 | AF22: =AE22*0.16 -> 452438.93 | AG22: =AE22*0.08 -> 226219.46 | AH22: =AE22+AF22+AG22 -> 3506401.7 | AI22: 3506402.5 | AJ22: NET MET | AK22: =SUM(Hoja2!O216:O246) -> 243 | AL22: =SUM(Hoja2!P216:P246) -> 457 | AM22: =SUM(Hoja2!Q216:Q246) -> 44 | AN22: =SUM(Hoja2!R216:R246) -> 48 | AO22: =SUM(Hoja2!S216:S246) -> 324 | AP22: =SUM(AN22:AO22) -> 372 | AQ22: =D22*AN22/AK22 -> 61671.506 | AR22: =E22*AO22/AL22 -> 451037.07 | AS22: =SUM(AQ22,AR22) -> 512708.57 | AT22: =AQ22/AS22 -> 0.12028569 | AU22: =AR22/AS22 -> 0.87971431 | AV22: =AS22/G22 -> 0.50409807 | AW22: 6.5503 | AX22: 0.85 | AY22: 0.62 | AZ22: =G22/(C22*AW22*AX22) -> 5892.6919 | BA22: =ROUNDUP(AZ22/AY22,0) -> 9505 | BB22: =E22/(C22*AW22*AX22) -> 3685.8836 | BC22: =ROUNDUP(BB22/AY22,0) -> 5945 | BD22: =AS22/(C22*AW22*AX22) -> 2970.4946 | BE22: =ROUNDUP(BD22/AY22,0) -> 4792 | BF22: =4560*AY22 -> 2827.2 | BG22: =BF22*C22*AW22*AX22 -> 487975.87 | BH22: =BG22*AT22 -> 58696.515 | BI22: =BG22*AU22 -> 429279.35 | BJ22: =ROUNDUP(BG22-AS22,0) -> -24733 | BK22: =D22-BH22 -> 253515.48 | BL22: =E22-BI22 -> 206905.65 | BM22: =IF(BJ22<0,G22-BG22,G22-BG22+BJ22) -> 529105.13 | BN22: =IF(BJ22<0,BG22/G22,(BG22-BJ22)/G22) -> 0.47978073 | BO22: =BK22 -> 253515.48 | BP22: =BL22 -> 206905.65 | BQ22: =F22 -> 68684 | BR22: =SUM(BO22:BQ22) -> 529105.13 | BS22: =BR22/(24*C22*0.57) -> 1247.6541 | BT22: =N22 -> 94.27 | BU22: =O22 -> 368.95 | BV22: =P22 -> 1.1585 | BW22: =Q22 -> 2.0765 | BX22: =R22 -> 2.3693 | BY22: =S22 -> 102.05 | BZ22: =T22 -> 439.43 | CA22: =BO22*BV22 -> 293697.69 | CB22: =BP22*BW22 -> 429639.58 | CC22: =BQ22*BX22 -> 162733 | CD22: =BS22*BY22 -> 127323.1 | CE22: =BS22*BZ22 -> 548256.62 | CF22: =SUM(CA22:CC22) -> 886070.27 | CG22: =AC22 -> 0.005 | CH22: =AD22 -> 14068.375 | CI22: =SUM(BU22,CF22,CH22) -> 900507.6 | CJ22: =CI22*0.16 -> 144081.22 | CK22: =CI22*0.08 -> 72040.608 | CL22: =SUM(CI22,CJ22,CK22) -> 1116629.4 | CM22: =AI22-CL22 -> 2389773
A23: 45900 | B23: 45930 | C23: =B23-A23 -> 30 | D23: 283090 | E23: 603860 | F23: 67117 | G23: =SUM(D23:F23) -> 954067 | H23: 1498 | I23: 1760 | J23: 1795 | K23: 1795 | L23: =G23/(24*C23*0.57) -> 2324.7247 | M23: 345944 | N23: 94.01 | O23: 368.95 | P23: 1.1538 | Q23: 2.0634 | R23: 2.3535 | S23: 102.05 | T23: 435.41 | U23: =MIN(J23,L23) -> 1795 | V23: =MIN(K23:L23) -> 1795 | W23: =D23*P23 -> 326629.24 | X23: =E23*Q23 -> 1246004.7 | Y23: =F23*R23 -> 157959.86 | Z23: =S23*V23 -> 183179.75 | AA23: =T23*U23 -> 781560.95 | AB23: =SUM(W23:AA23) -> 2695334.5 | AC23: =IF(N23<95,ROUND((3/5)*((95/N23)-1),3), ROUND((1/4)*(1-(90/N23)),3)) -> 0.006 | AD23: =(AB23+O23)*AC23 -> 16174.221 | AE23: =SUM(O23,AB23,AD23) -> 2711877.7 | AF23: =AE23*0.16 -> 433900.43 | AG23: =AE23*0.08 -> 216950.22 | AH23: =AE23+AF23+AG23 -> 3362728.3 | AI23: 3145778.6 | AJ23: NET MET | AK23: =SUM(Hoja2!O247:O276) -> 249 | AL23: =SUM(Hoja2!P247:P276) -> 429 | AM23: =SUM(Hoja2!Q247:Q276) -> 42 | AN23: =SUM(Hoja2!R247:R276) -> 60 | AO23: =SUM(Hoja2!S247:S276) -> 300 | AP23: =SUM(AN23:AO23) -> 360 | AQ23: =D23*AN23/AK23 -> 68214.458 | AR23: =E23*AO23/AL23 -> 422279.72 | AS23: =SUM(AQ23,AR23) -> 490494.18 | AT23: =AQ23/AS23 -> 0.13907292 | AU23: =AR23/AS23 -> 0.86092708 | AV23: =AS23/G23 -> 0.51410873 | AW23: 5.3508 | AX23: 0.85 | AY23: 0.62 | AZ23: =G23/(C23*AW23*AX23) -> 6992.2988 | BA23: =ROUNDUP(AZ23/AY23,0) -> 11278 | BB23: =E23/(C23*AW23*AX23) -> 4425.653 | BC23: =ROUNDUP(BB23/AY23,0) -> 7139 | BD23: =AS23/(C23*AW23*AX23) -> 3594.8019 | BE23: =ROUNDUP(BD23/AY23,0) -> 5799 | BF23: =4560*AY23 -> 2827.2 | BG23: =BF23*C23*AW23*AX23 -> 385758.43 | BH23: =BG23*AT23 -> 53648.552 | BI23: =BG23*AU23 -> 332109.88 | BJ23: =ROUNDUP(BG23-AS23,0) -> -104736 | BK23: =D23-BH23 -> 229441.45 | BL23: =E23-BI23 -> 271750.12 | BM23: =IF(BJ23<0,G23-BG23,G23-BG23+BJ23) -> 568308.57 | BN23: =IF(BJ23<0,BG23/G23,(BG23-BJ23)/G23) -> 0.40433055 | BO23: =BK23 -> 229441.45 | BP23: =BL23 -> 271750.12 | BQ23: =F23 -> 67117 | BR23: =SUM(BO23:BQ23) -> 568308.57 | BS23: =BR23/(24*C23*0.57) -> 1384.7675 | BT23: =N23 -> 94.01 | BU23: =O23 -> 368.95 | BV23: =P23 -> 1.1538 | BW23: =Q23 -> 2.0634 | BX23: =R23 -> 2.3535 | BY23: =S23 -> 102.05 | BZ23: =T23 -> 435.41 | CA23: =BO23*BV23 -> 264729.54 | CB23: =BP23*BW23 -> 560729.19 | CC23: =BQ23*BX23 -> 157959.86 | CD23: =BS23*BY23 -> 141315.52 | CE23: =BS23*BZ23 -> 602941.6 | CF23: =SUM(CA23:CC23) -> 983418.59 | CG23: =AC23 -> 0.006 | CH23: =AD23 -> 16174.221 | CI23: =SUM(BU23,CF23,CH23) -> 999961.76 | CJ23: =CI23*0.16 -> 159993.88 | CK23: =CI23*0.08 -> 79996.941 | CL23: =SUM(CI23,CJ23,CK23) -> 1239952.6 | CM23: =AI23-CL23 -> 1905826
AY24: MÁX | AZ24: =MAX(AZ3:AZ23) -> 8111.73 | BA24: =MAX(BA3:BA23) -> 13084 | BB24: =MAX(BB3:BB23) -> 4668.3403 | BC24: =MAX(BC3:BC23) -> 7530 | BD24: =MAX(BD3:BD23) -> 4068.3125 | BE24: =MAX(BE3:BE23) -> 6562 | BF24: MÁX | BG24: =MAX(BG3:BG23) -> 586274.29 | BH24: =MAX(BH3:BH23) -> 90205.515 | BI24: =MAX(BI3:BI23) -> 513441.07 | BJ24: =MAX(BJ3:BJ23) -> 178335 | BK24: =MAX(BK3:BK23) -> 275508.23 | BL24: =MAX(BL3:BL23) -> 317210.68 | BM24: =MAX(BM3:BM23) -> 661205.78 | BN24: =MAX(BN3:BN23) -> 0.51505178 | CL24: PROMEDIO/MES | CM24: =AVERAGE(CM3:CM23) -> 2208939.6
AY25: MÍN | AZ25: =MIN(AZ3:AZ23) -> 3761.3735 | BA25: =MIN(BA3:BA23) -> 6067 | BB25: =MIN(BB3:BB23) -> 2335.0519 | BC25: =MIN(BC3:BC23) -> 3767 | BD25: =MIN(BD3:BD23) -> 1937.307 | BE25: =MIN(BE3:BE23) -> 3125 | BF25: MÍN | BG25: =MIN(BG3:BG23) -> 341634.51 | BH25: =MIN(BH3:BH23) -> 42619.803 | BI25: =MIN(BI3:BI23) -> 286735.96 | BJ25: =MIN(BJ3:BJ23) -> -149975 | BK25: =MIN(BK3:BK23) -> 160138.37 | BL25: =MIN(BL3:BL23) -> -29431.555 | BM25: =MIN(BM3:BM23) -> 365542.82 | BN25: =MIN(BN3:BN23) -> 0.34853231 | CL25: INVERSIÓN | CM25: RETORNO DE INVERSIÓN MES | CN25: RETORNO DE INVERSIÓN AÑOS
AY26: PROMEDIO | AZ26: =AVERAGE(AZ3:AZ23) -> 6432.1492 | BA26: =AVERAGE(BA3:BA23) -> 10374.952 | BB26: =AVERAGE(BB3:BB23) -> 3807.4251 | BC26: =AVERAGE(BC3:BC23) -> 6141.4762 | BD26: =AVERAGE(BD3:BD23) -> 3248.4715 | BE26: =AVERAGE(BE3:BE23) -> 5239.9048 | BF26: PROMEDIO | BG26: =AVERAGE(BG3:BG23) -> 452585.33 | BH26: =AVERAGE(BH3:BH23) -> 60316.525 | BI26: =AVERAGE(BI3:BI23) -> 392268.81 | BJ26: =AVERAGE(BJ3:BJ23) -> -55206.143 | BK26: =AVERAGE(BK3:BK23) -> 246377.14 | BL26: =AVERAGE(BL3:BL23) -> 205413.43 | BM26: =AVERAGE(BM3:BM23) -> 567803.33 | BN26: =AVERAGE(BN3:BN23) -> 0.43511749 | CL26: 52000000 | CM26: =ROUNDUP(CL26/CM24,0) -> 24 | CN26: =CM26/12 -> 2
AY27: PERCENTIL 95% | AZ27: =PERCENTILE(AZ3:AZ23,0.95) -> 7716.5017 | BA27: =PERCENTILE(BA3:BA23,0.95) -> 12446 | BB27: =PERCENTILE(BB3:BB23,0.95) -> 4646.2614 | BC27: =PERCENTILE(BC3:BC23,0.95) -> 7494 | BD27: =PERCENTILE(BD3:BD23,0.95) -> 3916.2533 | BE27: =PERCENTILE(BE3:BE23,0.95) -> 6317 | BF27: PERCENTIL 95% | BG27: =PERCENTILE(BG3:BG23,0.95) -> 566569.18 | BH27: =PERCENTILE(BH3:BH23,0.95) -> 77241.612 | BI27: =PERCENTILE(BI3:BI23,0.95) -> 497374.56 | BJ27: =PERCENTILE(BJ3:BJ23,0.95) -> 60903 | BK27: =PERCENTILE(BK3:BK23,0.95) -> 271731.34 | BL27: =PERCENTILE(BL3:BL23,0.95) -> 306942.23 | BM27: =PERCENTILE(BM3:BM23,0.95) -> 647778.57 | BN27: =PERCENTILE(BN3:BN23,0.95) -> 0.50240054

Sheet Hoja2
A1: DÍA DE LA SEMANA | B1: DÍA | C1: MES | D1: AÑO | E1: LUNES A VIERNES | I1: SÁBADO | M1: DOMINGO Y FESTIVO | O1: TOTAL DE HORAS | R1: HORAS SOLARES
A2: PERIODO HORARIO | E2: BASE | F2: INTERMEDIO | G2: PUNTA | H2: INTERMEDIO | I2: BASE | J2: INTERMEDIO | K2: PUNTA | L2: INTERMEDIO | M2: BASE | N2: INTERMEDIO
A3: INVIERNO | E3: =Hoja3!I11 -> 0.25 | F3: =Hoja3!I12 -> 0.5 | G3: =Hoja3!I13 -> 0.16666667 | H3: =Hoja3!I14 -> 0.083333333 | I3: =Hoja3!I15 -> 0.33333333 | J3: =Hoja3!I16 -> 0.45833333 | K3: =Hoja3!I17 -> 0.083333333 | L3: =Hoja3!I18 -> 0.125 | M3: =Hoja3!I19 -> 0.75 | N3: =Hoja3!I20 -> 0.25
A4: VERANO | E4: 0.25 | F4: 0.58333333 | G4: 0.083333333 | H4: 0.083333333 | I4: 0.29166667 | J4: 0.70833333 | K4: 0 | L4: 0 | M4: 0.79166667 | N4: 0.20833333 | O4: BASE | P4: INTERMEDIO | Q4: PUNTA | R4: BASE | S4: INTERMEDIO
A5: MIÉRCOLES | B5: 1 | C5: ENERO | D5: 2025 | E5: 6 | F5: 12 | G5: 4 | H5: 2 | I5: 0 | J5: 0 | K5: 0 | L5: 0 | M5: 0 | N5: 0 | O5: =SUM(E5,I5,M5) -> 6 | P5: =SUM(F5,H5,J5,L5,N5) -> 14 | Q5: =SUM(G5,K5) -> 4 | R5: 0 | S5: 12
A6: JUEVES | B6: 2 | C6: ENERO | D6: 2025 | E6: 6 | F6: 12 | G6: 4 | H6: 2 | I6: 0 | J6: 0 | K6: 0 | L6: 0 | M6: 0 | N6: 0 | O6: =SUM(E6,I6,M6) -> 6 | P6: =SUM(F6,H6,J6,L6,N6) -> 14 | Q6: =SUM(G6,K6) -> 4 | R6: 0 | S6: 12
